<?xml version="1.0" ?>
<!-- =================================================================================== -->
<!-- |    This document was autogenerated by xacro from omnirob.urdf.xacro             | -->
<!-- |    EDITING THIS FILE BY HAND IS NOT RECOMMENDED                                 | -->
<!-- =================================================================================== -->
<robot name="omniRob" xmlns:controller="http://playerstage.sourceforge.net/gazebo/xmlschema/#controller" xmlns:interface="http://playerstage.sourceforge.net/gazebo/xmlschema/#interface" xmlns:sensor="http://playerstage.sourceforge.net/gazebo/xmlschema/#sensor" xmlns:xacro="http://ros.org/wiki/xacro">
  <link name="base_link"/>
  <link name="omnirob_base_x"/>
  <link name="omnirob_base_y"/>
  <link name="omnirob_platform">
    <visual>
      <geometry>
        <mesh filename="package://ros_omnirob_description/meshes/OMNIROB_base.dae" scale="1 1 1"/>
      </geometry>
      <origin rpy="0 0 0" xyz="0 0 0"/>
    </visual>
    <collision>
      <geometry>
        <mesh filename="package://ros_omnirob_description/meshes/OMNIROB_base_hull.stl" scale="1 1 1"/>
      </geometry>
      <origin rpy="0 0 0" xyz="0 0 0"/>
    </collision>
  </link>
  <link name="omnirob_connector">
    <visual>
      <geometry>
        <mesh filename="package://ros_omnirob_description/meshes/OMNIROB_connector.dae" scale="1 1 1"/>
      </geometry>
      <origin rpy="0 0 0" xyz="0 0 0"/>
    </visual>
    <collision>
      <geometry>
        <mesh filename="package://ros_omnirob_description/meshes/OMNIROB_connector.stl" scale="1 1 1"/>
      </geometry>
      <origin rpy="0 0 0" xyz="0 0 0"/>
    </collision>
  </link>
  <link name="omnirob_left_lwr_base"/>
  <link name="omnirob_right_lwr_base"/>
  <!-- utils /-->
  <!-- Little helper macro to define the inertia matrix needed for links. -->
  <!-- length is along the y-axis! -->
  <material name="Kuka/DarkGrey">
    <color rgba="0.3 0.3 0.3 1.0"/>
  </material>
  <material name="Kuka/LightGrey">
    <color rgba="0.8 0.8 0.8 1.0"/>
  </material>
  <material name="Kuka/Red">
    <color rgba="0.3 0.3 0.3 1.0"/>
  </material>
  <material name="Kuka/Black">
    <color rgba="0 0 0 1.0"/>
  </material>
  <material name="Kuka/Orange">
    <color rgba="1.0 0.487 0 1.0"/>
  </material>
  <material name="Kuka/Silver">
    <color rgba="1.0 1.0 1.0 1.0"/>
  </material>
  <material name="Kuka/Grey">
    <color rgba="0.7 0.7 0.7 1.0"/>
  </material>
  <material name="Kuka/Blue">
    <color rgba="0.0 0.0 0.8 1.0"/>
  </material>
  <!-- gazebo and transmission models /-->
  <!-- properties /-->
  <!-- reflex to stiffness -->
  <!-- URDF model /-->
  <!-- First (shoulder) element of the arm. Fixed to its parent. -->
  <joint name="omnirob_left_lwr_base_omnirob_left_lwr_base_joint" type="fixed">
    <origin rpy="0 0 0" xyz="0 0 0"/>
    <origin rpy="0 0 0" xyz="0 0 0"/>
    <parent link="omnirob_left_lwr_base"/>
    <child link="omnirob_left_lwr_base_link"/>
  </joint>
  <link name="omnirob_left_lwr_base_link">
    <inertial>
      <mass value="2.0"/>
      <origin xyz="0 0 0.055"/>
      <inertia ixx="0.00381666666667" ixy="0" ixz="0" iyy="0.0036" iyz="0" izz="0.00381666666667"/>
    </inertial>
    <visual>
      <origin rpy="0 0 3.14159265359" xyz="0 0 0"/>
      <geometry>
        <mesh filename="package://lwr_description/meshes/base.STL"/>
      </geometry>
      <material name="Kuka/Orange"/>
    </visual>
    <collision>
      <origin rpy="0 0 3.14159265359" xyz="0 0 0.055"/>
      <geometry>
        <mesh filename="package://lwr_description/meshes/convex/arm_base_convex.stl"/>
      </geometry>
    </collision>
  </link>
  <!-- Second segment of the arm. Joint along z-axis -->
  <joint name="omnirob_left_lwr_0_joint" type="revolute">
    <origin rpy="0 0 0" xyz="0 0 0.11"/>
    <axis xyz="0 0 1"/>
    <limit effort="176" lower="-2.96705972839" upper="2.96705972839" velocity="1.91986217719"/>
    <dynamics damping="1.0" friction="10.0"/>
    <parent link="omnirob_left_lwr_base_link"/>
    <child link="omnirob_left_lwr_1_link"/>
  </joint>
  <link name="omnirob_left_lwr_1_link">
    <inertial>
      <mass value="2.0"/>
      <origin rpy="0 0 0" xyz="0 -0.06 0.130"/>
      <inertia ixx="0.0136666666667" ixy="0" ixz="0" iyy="0.003" iyz="0" izz="0.0118666666667"/>
    </inertial>
    <visual>
      <origin rpy="0 0 3.14159265359" xyz="0 0 -0.008"/>
      <geometry>
        <mesh filename="package://lwr_description/meshes/link_1.STL"/>
      </geometry>
      <material name="Kuka/Orange"/>
    </visual>
    <collision>
      <origin rpy="0 0 3.14159265359" xyz="0 0 -0.008"/>
      <geometry>
        <mesh filename="package://lwr_description/meshes/convex/arm_segment_a_convex.stl"/>
      </geometry>
    </collision>    
  </link>
  <!-- Third segment of the arm. Joint along y-axis -->
  <joint name="omnirob_left_lwr_1_joint" type="revolute">
    <origin rpy="0 0 0" xyz="0 0 0.2005"/>
    <axis xyz="0 -1 0"/>
    <limit effort="176" lower="-2.09439510239" upper="2.09439510239" velocity="1.91986217719"/>
    <dynamics damping="1.0" friction="10.0"/>
    <parent link="omnirob_left_lwr_1_link"/>
    <child link="omnirob_left_lwr_2_link"/>
  </joint>
  <link name="omnirob_left_lwr_2_link">
    <inertial>
      <mass value="2.0"/>
      <origin rpy="0 0 0" xyz="0 0.06 0.07"/>
      <inertia ixx="0.0136666666667" ixy="0" ixz="0" iyy="0.003" iyz="0" izz="0.0118666666667"/>
    </inertial>
    <visual>
      <origin rpy="0 0 3.14159265359" xyz="0 0 0.0"/>
      <geometry>
        <mesh filename="package://lwr_description/meshes/link_2.STL"/>
      </geometry>
      <material name="Kuka/Orange"/>
    </visual>
    <collision>
      <origin rpy="0 0 3.14159265359" xyz="0 0 0.0"/>
      <geometry>
        <mesh filename="package://lwr_description/meshes/convex/arm_segment_b_convex.stl"/>
      </geometry>
    </collision>
  </link>
  <!-- Fourth element of the arm. z-axis -->
  <joint name="omnirob_left_lwr_2_joint" type="revolute">
    <origin rpy="0 0 0" xyz="0 0 0.20"/>
    <axis xyz="0 0 1"/>
    <limit effort="100" lower="-2.96705972839" upper="2.96705972839" velocity="2.23402144255"/>
    <dynamics damping="1.0" friction="10.0"/>
    <parent link="omnirob_left_lwr_2_link"/>
    <child link="omnirob_left_lwr_3_link"/>
  </joint>
  <link name="omnirob_left_lwr_3_link">
    <inertial>
      <mass value="2.0"/>
      <origin rpy="0 0 0" xyz="0 0.06 0.130"/>
      <inertia ixx="0.0136666666667" ixy="0" ixz="0" iyy="0.003" iyz="0" izz="0.0118666666667"/>
    </inertial>
    <visual>
      <origin rpy="0 0 3.14159265359" xyz="0 0 -0.008"/>
      <geometry>
        <mesh filename="package://lwr_description/meshes/link_3.STL"/>
      </geometry>
      <material name="Kuka/Orange"/>
    </visual>
    <collision>
      <origin rpy="0 0 3.14159265359" xyz="0 0 -0.008"/>
      <geometry>
        <mesh filename="package://lwr_description/meshes/convex/arm_segment_a_convex.stl"/>
      </geometry>
    </collision>
  </link>
  <!-- fifth element of the arm. x-axis -->
  <joint name="omnirob_left_lwr_3_joint" type="revolute">
    <origin rpy="0 0 0" xyz="0 0 0.20"/>
    <axis xyz="0 1 0"/>
    <limit effort="100" lower="-2.09439510239" upper="2.09439510239" velocity="2.23402144255"/>
    <dynamics damping="1.0" friction="10.0"/>
    <parent link="omnirob_left_lwr_3_link"/>
    <child link="omnirob_left_lwr_4_link"/>
  </joint>
  <link name="omnirob_left_lwr_4_link">
    <inertial>
      <mass value="2.0"/>
      <origin rpy="0 0 0" xyz="0 -0.06 0.07"/>
      <inertia ixx="0.0136666666667" ixy="0" ixz="0" iyy="0.003" iyz="0" izz="0.0118666666667"/>
    </inertial>
    <visual>
      <origin rpy="0 0 3.14159265359" xyz="0 0 0.0"/>
      <geometry>
        <mesh filename="package://lwr_description/meshes/link_4.STL"/>
      </geometry>
      <material name="Kuka/Orange"/>
    </visual>
    <collision>
      <origin rpy="0 0 3.14159265359" xyz="0 0 0.0"/>
      <geometry>
        <mesh filename="package://lwr_description/meshes/convex/arm_segment_b_convex.stl"/>
      </geometry>
    </collision>
  </link>
  <!-- Sixth element of the arm. z-axis -->
  <joint name="omnirob_left_lwr_4_joint" type="revolute">
    <origin rpy="0 0 0" xyz="0 0 0.20"/>
    <axis xyz="0 0 1"/>
    <limit effort="100" lower="-2.96705972839" upper="2.96705972839" velocity="3.56047167407"/>
    <dynamics damping="1.0" friction="10.0"/>
    <parent link="omnirob_left_lwr_4_link"/>
    <child link="omnirob_left_lwr_5_link"/>
  </joint>
  <link name="omnirob_left_lwr_5_link">
    <inertial>
      <mass value="2.0"/>
      <origin rpy="0 0 0" xyz="0 0 0.124"/>
      <inertia ixx="0.0126506666667" ixy="0" ixz="0" iyy="0.003" iyz="0" izz="0.0108506666667"/>
    </inertial>
    <visual>
      <origin rpy="0 0 3.14159265359" xyz="0 0 -0.008"/>
      <geometry name="omnirob_left_lwr_5_geom">
        <mesh filename="package://lwr_description/meshes/link_5.STL"/>
      </geometry>
      <material name="Kuka/Orange"/>
    </visual>
    <collision>
      <origin rpy="0 0 3.14159265359" xyz="0 0 -0.008"/>
      <geometry>
        <mesh filename="package://lwr_description/meshes/convex/arm_segment_last_convex.stl"/>
      </geometry>
    </collision>
  </link>
  <!-- Seventh element of the arm. z-axis -->
  <joint name="omnirob_left_lwr_5_joint" type="revolute">
    <origin rpy="0 0 0" xyz="0 0 0.19"/>
    <axis xyz="0 -1 0"/>
    <limit effort="38" lower="-2.09439510239" upper="2.09439510239" velocity="3.21140582367"/>
    <dynamics damping="1.0" friction="10.0"/>
    <parent link="omnirob_left_lwr_5_link"/>
    <child link="omnirob_left_lwr_6_link"/>
  </joint>
  <link name="omnirob_left_lwr_6_link">
    <inertial>
      <mass value="0.2"/>
      <origin rpy="0 0 0" xyz="0 0 0.0625"/>
      <inertia ixx="0.000520833333333" ixy="0" ixz="0" iyy="0.000520833333333" iyz="0" izz="0.000520833333333"/>
    </inertial>
    <visual>
      <origin rpy="0 0 3.14159265359" xyz="0 0 0"/>
      <geometry>
        <mesh filename="package://lwr_description/meshes/link_6.STL"/>
      </geometry>
      <material name="Kuka/Grey"/>
    </visual>
    <collision>
      <origin rpy="0 0 3.14159265359" xyz="0 0 0"/>
      <geometry>
        <mesh filename="package://lwr_description/meshes/convex/arm_wrist_convex.stl"/>
      </geometry>
    </collision>
  </link>
  <!-- Eighth element of the arm. z-axis -->
  <joint name="omnirob_left_lwr_6_joint" type="revolute">
    <origin rpy="0 0 0" xyz="0 0 0.078"/>
    <axis xyz="0 0 1"/>
    <limit effort="38" lower="-2.96705972839" upper="2.96705972839" velocity="3.21140582367"/>
    <dynamics damping="1.0" friction="10.0"/>
    <parent link="omnirob_left_lwr_6_link"/>
    <child link="omnirob_left_lwr_7_link"/>
  </joint>
  <link name="omnirob_left_lwr_7_link">
    <inertial>
      <mass value="0.2"/>
      <origin xyz="0 0 0"/>
      <inertia ixx="0.0333333333333" ixy="0" ixz="0" iyy="0.0333333333333" iyz="0" izz="0.0333333333333"/>
    </inertial>
    <visual>
      <origin rpy="0 0 3.14159265359" xyz="0 0 0"/>
      <geometry>
        <mesh filename="package://lwr_description/meshes/link_7.STL"/>
      </geometry>
      <material name="Kuka/DarkGrey"/>
    </visual>
    <collision>
      <origin rpy="0 0 3.14159265359" xyz="0 0 0"/>
      <geometry>
        <cylinder length="0.05" radius="0.04"/>
      </geometry>
    </collision>
  </link>
  <gazebo>
    <plugin filename="liblwr_hw_gazebo_plugin.so" name="omnirob_left_lwr_lwr_hw_sim">
      <robotNamespace>omnirob_left_lwr</robotNamespace>
    </plugin>
  </gazebo>
  <gazebo reference="omnirob_left_lwr_base_link">
    <gravity>true</gravity>
    <material>Gazebo/Orange</material>
  </gazebo>
  <gazebo reference="omnirob_left_lwr_1_link">
    <gravity>true</gravity>
    <material>Gazebo/Orange</material>
  </gazebo>
  <gazebo reference="omnirob_left_lwr_2_link">
    <gravity>true</gravity>
    <material>Gazebo/Orange</material>
  </gazebo>
  <gazebo reference="omnirob_left_lwr_3_link">
    <gravity>true</gravity>
    <material>Gazebo/Orange</material>
  </gazebo>
  <gazebo reference="omnirob_left_lwr_4_link">
    <gravity>true</gravity>
    <material>Gazebo/Orange</material>
  </gazebo>
  <gazebo reference="omnirob_left_lwr_5_link">
    <gravity>true</gravity>
    <material>Gazebo/Orange</material>
  </gazebo>
  <gazebo reference="omnirob_left_lwr_6_link">
    <gravity>true</gravity>
    <material>Gazebo/Orange</material>
  </gazebo>
  <gazebo reference="omnirob_left_lwr_7_link">
    <gravity>true</gravity>
    <material>Gazebo/Grey</material>
  </gazebo>
  <transmission name="omnirob_left_lwr_0_trans">
    <type>transmission_interface/SimpleTransmission</type>
    <joint name="omnirob_left_lwr_0_joint">
      <hardwareInterface>PositionJointInterface</hardwareInterface>
      <hardwareInterface>EffortJointInterface</hardwareInterface>
    </joint>
    <actuator name="omnirob_left_lwr_0_motor">
      <mechanicalReduction>1</mechanicalReduction>
    </actuator>
  </transmission>
  <transmission name="omnirob_left_lwr_1_trans">
    <type>transmission_interface/SimpleTransmission</type>
    <joint name="omnirob_left_lwr_1_joint">
      <hardwareInterface>PositionJointInterface</hardwareInterface>
      <hardwareInterface>EffortJointInterface</hardwareInterface>
    </joint>
    <actuator name="omnirob_left_lwr_1_motor">
      <mechanicalReduction>1</mechanicalReduction>
    </actuator>
  </transmission>
  <transmission name="omnirob_left_lwr_2_trans">
    <type>transmission_interface/SimpleTransmission</type>
    <joint name="omnirob_left_lwr_2_joint">
      <hardwareInterface>PositionJointInterface</hardwareInterface>
      <hardwareInterface>EffortJointInterface</hardwareInterface>
    </joint>
    <actuator name="omnirob_left_lwr_2_motor">
      <mechanicalReduction>1</mechanicalReduction>
    </actuator>
  </transmission>
  <transmission name="omnirob_left_lwr_3_trans">
    <type>transmission_interface/SimpleTransmission</type>
    <joint name="omnirob_left_lwr_3_joint">
      <hardwareInterface>PositionJointInterface</hardwareInterface>
      <hardwareInterface>EffortJointInterface</hardwareInterface>
    </joint>
    <actuator name="omnirob_left_lwr_3_motor">
      <mechanicalReduction>1</mechanicalReduction>
    </actuator>
  </transmission>
  <transmission name="omnirob_left_lwr_4_trans">
    <type>transmission_interface/SimpleTransmission</type>
    <joint name="omnirob_left_lwr_4_joint">
      <hardwareInterface>PositionJointInterface</hardwareInterface>
      <hardwareInterface>EffortJointInterface</hardwareInterface>
    </joint>
    <actuator name="omnirob_left_lwr_4_motor">
      <mechanicalReduction>1</mechanicalReduction>
    </actuator>
  </transmission>
  <transmission name="omnirob_left_lwr_5_trans">
    <type>transmission_interface/SimpleTransmission</type>
    <joint name="omnirob_left_lwr_5_joint">
      <hardwareInterface>PositionJointInterface</hardwareInterface>
      <hardwareInterface>EffortJointInterface</hardwareInterface>
    </joint>
    <actuator name="omnirob_left_lwr_5_motor">
      <mechanicalReduction>1</mechanicalReduction>
    </actuator>
  </transmission>
  <transmission name="omnirob_left_lwr_6_trans">
    <type>transmission_interface/SimpleTransmission</type>
    <joint name="omnirob_left_lwr_6_joint">
      <hardwareInterface>PositionJointInterface</hardwareInterface>
      <hardwareInterface>EffortJointInterface</hardwareInterface>
    </joint>
    <actuator name="omnirob_left_lwr_6_motor">
      <mechanicalReduction>1</mechanicalReduction>
    </actuator>
  </transmission>
  <!-- First (shoulder) element of the arm. Fixed to its parent. -->
  <joint name="omnirob_right_lwr_base_omnirob_right_lwr_base_joint" type="fixed">
    <origin rpy="0 0 0" xyz="0 0 0"/>
    <origin rpy="0 0 0" xyz="0 0 0"/>
    <parent link="omnirob_right_lwr_base"/>
    <child link="omnirob_right_lwr_base_link"/>
  </joint>
  <link name="omnirob_right_lwr_base_link">
    <inertial>
      <mass value="2.0"/>
      <origin xyz="0 0 0.055"/>
      <inertia ixx="0.00381666666667" ixy="0" ixz="0" iyy="0.0036" iyz="0" izz="0.00381666666667"/>
    </inertial>
    <visual>
      <origin rpy="0 0 3.14159265359" xyz="0 0 0"/>
      <geometry>
        <mesh filename="package://lwr_description/meshes/base.STL"/>
      </geometry>
      <material name="Kuka/Orange"/>
    </visual>
    <collision>
      <origin rpy="0 0 3.14159265359" xyz="0 0 0.055"/>
      <geometry>
        <mesh filename="package://lwr_description/meshes/convex/arm_base_convex.stl"/>
      </geometry>
    </collision>
  </link>
  <!-- Second segment of the arm. Joint along z-axis -->
  <joint name="omnirob_right_lwr_0_joint" type="revolute">
    <origin rpy="0 0 0" xyz="0 0 0.11"/>
    <axis xyz="0 0 1"/>
    <limit effort="176" lower="-2.96705972839" upper="2.96705972839" velocity="1.91986217719"/>
    <dynamics damping="1.0" friction="10.0"/>
    <parent link="omnirob_right_lwr_base_link"/>
    <child link="omnirob_right_lwr_1_link"/>
  </joint>
  <link name="omnirob_right_lwr_1_link">
    <inertial>
      <mass value="2.0"/>
      <origin rpy="0 0 0" xyz="0 -0.06 0.130"/>
      <inertia ixx="0.0136666666667" ixy="0" ixz="0" iyy="0.003" iyz="0" izz="0.0118666666667"/>
    </inertial>
    <visual>
      <origin rpy="0 0 3.14159265359" xyz="0 0 -0.008"/>
      <geometry>
        <mesh filename="package://lwr_description/meshes/link_1.STL"/>
      </geometry>
      <material name="Kuka/Orange"/>
    </visual>
    <collision>
      <origin rpy="0 0 3.14159265359" xyz="0 0 -0.008"/>
      <geometry>
        <mesh filename="package://lwr_description/meshes/convex/arm_segment_a_convex.stl"/>
      </geometry>
    </collision>
  </link>
  <!-- Third segment of the arm. Joint along y-axis -->
  <joint name="omnirob_right_lwr_1_joint" type="revolute">
    <origin rpy="0 0 0" xyz="0 0 0.2005"/>
    <axis xyz="0 -1 0"/>
    <limit effort="176" lower="-2.09439510239" upper="2.09439510239" velocity="1.91986217719"/>
    <dynamics damping="1.0" friction="10.0"/>
    <parent link="omnirob_right_lwr_1_link"/>
    <child link="omnirob_right_lwr_2_link"/>
  </joint>
  <link name="omnirob_right_lwr_2_link">
    <inertial>
      <mass value="2.0"/>
      <origin rpy="0 0 0" xyz="0 0.06 0.07"/>
      <inertia ixx="0.0136666666667" ixy="0" ixz="0" iyy="0.003" iyz="0" izz="0.0118666666667"/>
    </inertial>
    <visual>
      <origin rpy="0 0 3.14159265359" xyz="0 0 0.0"/>
      <geometry>
        <mesh filename="package://lwr_description/meshes/link_2.STL"/>
      </geometry>
      <material name="Kuka/Orange"/>
    </visual>
    <collision>
      <origin rpy="0 0 3.14159265359" xyz="0 0 0.0"/>
      <geometry>
        <mesh filename="package://lwr_description/meshes/convex/arm_segment_b_convex.stl"/>
      </geometry>
    </collision>
  </link>
  <!-- Fourth element of the arm. z-axis -->
  <joint name="omnirob_right_lwr_2_joint" type="revolute">
    <origin rpy="0 0 0" xyz="0 0 0.20"/>
    <axis xyz="0 0 1"/>
    <limit effort="100" lower="-2.96705972839" upper="2.96705972839" velocity="2.23402144255"/>
    <dynamics damping="1.0" friction="10.0"/>
    <parent link="omnirob_right_lwr_2_link"/>
    <child link="omnirob_right_lwr_3_link"/>
  </joint>
  <link name="omnirob_right_lwr_3_link">
    <inertial>
      <mass value="2.0"/>
      <origin rpy="0 0 0" xyz="0 0.06 0.130"/>
      <inertia ixx="0.0136666666667" ixy="0" ixz="0" iyy="0.003" iyz="0" izz="0.0118666666667"/>
    </inertial>
    <visual>
      <origin rpy="0 0 3.14159265359" xyz="0 0 -0.008"/>
      <geometry>
        <mesh filename="package://lwr_description/meshes/link_3.STL"/>
      </geometry>
      <material name="Kuka/Orange"/>
    </visual>
    <collision>
      <origin rpy="0 0 3.14159265359" xyz="0 0 -0.008"/>
      <geometry>
        <mesh filename="package://lwr_description/meshes/convex/arm_segment_a_convex.stl"/>
      </geometry>
    </collision>
  </link>
  <!-- fifth element of the arm. x-axis -->
  <joint name="omnirob_right_lwr_3_joint" type="revolute">
    <origin rpy="0 0 0" xyz="0 0 0.20"/>
    <axis xyz="0 1 0"/>
    <limit effort="100" lower="-2.09439510239" upper="2.09439510239" velocity="2.23402144255"/>
    <dynamics damping="1.0" friction="10.0"/>
    <parent link="omnirob_right_lwr_3_link"/>
    <child link="omnirob_right_lwr_4_link"/>
  </joint>
  <link name="omnirob_right_lwr_4_link">
    <inertial>
      <mass value="2.0"/>
      <origin rpy="0 0 0" xyz="0 -0.06 0.07"/>
      <inertia ixx="0.0136666666667" ixy="0" ixz="0" iyy="0.003" iyz="0" izz="0.0118666666667"/>
    </inertial>
    <visual>
      <origin rpy="0 0 3.14159265359" xyz="0 0 0.0"/>
      <geometry>
        <mesh filename="package://lwr_description/meshes/link_4.STL"/>
      </geometry>
      <material name="Kuka/Orange"/>
    </visual>
    <collision>
      <origin rpy="0 0 3.14159265359" xyz="0 0 0.0"/>
      <geometry>
        <mesh filename="package://lwr_description/meshes/convex/arm_segment_b_convex.stl"/>
      </geometry>
    </collision>
  </link>
  <!-- Sixth element of the arm. z-axis -->
  <joint name="omnirob_right_lwr_4_joint" type="revolute">
    <origin rpy="0 0 0" xyz="0 0 0.20"/>
    <axis xyz="0 0 1"/>
    <limit effort="100" lower="-2.96705972839" upper="2.96705972839" velocity="3.56047167407"/>
    <dynamics damping="1.0" friction="10.0"/>
    <parent link="omnirob_right_lwr_4_link"/>
    <child link="omnirob_right_lwr_5_link"/>
  </joint>
  <link name="omnirob_right_lwr_5_link">
    <inertial>
      <mass value="2.0"/>
      <origin rpy="0 0 0" xyz="0 0 0.124"/>
      <inertia ixx="0.0126506666667" ixy="0" ixz="0" iyy="0.003" iyz="0" izz="0.0108506666667"/>
    </inertial>
    <visual>
      <origin rpy="0 0 3.14159265359" xyz="0 0 -0.008"/>
      <geometry name="omnirob_right_lwr_5_geom">
        <mesh filename="package://lwr_description/meshes/link_5.STL"/>
      </geometry>
      <material name="Kuka/Orange"/>
    </visual>
    <collision>
      <origin rpy="0 0 3.14159265359" xyz="0 0 -0.008"/>
      <geometry>
        <mesh filename="package://lwr_description/meshes/convex/arm_segment_last_convex.stl"/>
      </geometry>
    </collision>
  </link>
  <!-- Seventh element of the arm. z-axis -->
  <joint name="omnirob_right_lwr_5_joint" type="revolute">
    <origin rpy="0 0 0" xyz="0 0 0.19"/>
    <axis xyz="0 -1 0"/>
    <limit effort="38" lower="-2.09439510239" upper="2.09439510239" velocity="3.21140582367"/>
    <dynamics damping="1.0" friction="10.0"/>
    <parent link="omnirob_right_lwr_5_link"/>
    <child link="omnirob_right_lwr_6_link"/>
  </joint>
  <link name="omnirob_right_lwr_6_link">
    <inertial>
      <mass value="0.2"/>
      <origin rpy="0 0 0" xyz="0 0 0.0625"/>
      <inertia ixx="0.000520833333333" ixy="0" ixz="0" iyy="0.000520833333333" iyz="0" izz="0.000520833333333"/>
    </inertial>
    <visual>
      <origin rpy="0 0 3.14159265359" xyz="0 0 0"/>
      <geometry>
        <mesh filename="package://lwr_description/meshes/link_6.STL"/>
      </geometry>
      <material name="Kuka/Grey"/>
    </visual>
    <collision>
      <origin rpy="0 0 3.14159265359" xyz="0 0 0"/>
      <geometry>
        <mesh filename="package://lwr_description/meshes/convex/arm_wrist_convex.stl"/>
      </geometry>
    </collision>
  </link>
  <!-- Eighth element of the arm. z-axis -->
  <joint name="omnirob_right_lwr_6_joint" type="revolute">
    <origin rpy="0 0 0" xyz="0 0 0.078"/>
    <axis xyz="0 0 1"/>
    <limit effort="38" lower="-2.96705972839" upper="2.96705972839" velocity="3.21140582367"/>
    <dynamics damping="1.0" friction="10.0"/>
    <parent link="omnirob_right_lwr_6_link"/>
    <child link="omnirob_right_lwr_7_link"/>
  </joint>
  <link name="omnirob_right_lwr_7_link">
    <inertial>
      <mass value="0.2"/>
      <origin xyz="0 0 0"/>
      <inertia ixx="0.0333333333333" ixy="0" ixz="0" iyy="0.0333333333333" iyz="0" izz="0.0333333333333"/>
    </inertial>
    <visual>
      <origin rpy="0 0 3.14159265359" xyz="0 0 0"/>
      <geometry>
        <mesh filename="package://lwr_description/meshes/link_7.STL"/>
      </geometry>
      <material name="Kuka/DarkGrey"/>
    </visual>
    <collision>
      <origin rpy="0 0 3.14159265359" xyz="0 0 0"/>
      <geometry>
        <cylinder length="0.05" radius="0.04"/>
      </geometry>
    </collision>
  </link>
  <gazebo>
    <plugin filename="liblwr_hw_gazebo_plugin.so" name="omnirob_right_lwr_lwr_hw_sim">
      <robotNamespace>omnirob_right_lwr</robotNamespace>
    </plugin>
  </gazebo>
  <gazebo reference="omnirob_right_lwr_base_link">
    <gravity>true</gravity>
    <material>Gazebo/Orange</material>
  </gazebo>
  <gazebo reference="omnirob_right_lwr_1_link">
    <gravity>true</gravity>
    <material>Gazebo/Orange</material>
  </gazebo>
  <gazebo reference="omnirob_right_lwr_2_link">
    <gravity>true</gravity>
    <material>Gazebo/Orange</material>
  </gazebo>
  <gazebo reference="omnirob_right_lwr_3_link">
    <gravity>true</gravity>
    <material>Gazebo/Orange</material>
  </gazebo>
  <gazebo reference="omnirob_right_lwr_4_link">
    <gravity>true</gravity>
    <material>Gazebo/Orange</material>
  </gazebo>
  <gazebo reference="omnirob_right_lwr_5_link">
    <gravity>true</gravity>
    <material>Gazebo/Orange</material>
  </gazebo>
  <gazebo reference="omnirob_right_lwr_6_link">
    <gravity>true</gravity>
    <material>Gazebo/Orange</material>
  </gazebo>
  <gazebo reference="omnirob_right_lwr_7_link">
    <gravity>true</gravity>
    <material>Gazebo/Grey</material>
  </gazebo>
  <transmission name="omnirob_right_lwr_0_trans">
    <type>transmission_interface/SimpleTransmission</type>
    <joint name="omnirob_right_lwr_0_joint">
      <hardwareInterface>PositionJointInterface</hardwareInterface>
      <hardwareInterface>EffortJointInterface</hardwareInterface>
    </joint>
    <actuator name="omnirob_right_lwr_0_motor">
      <mechanicalReduction>1</mechanicalReduction>
    </actuator>
  </transmission>
  <transmission name="omnirob_right_lwr_1_trans">
    <type>transmission_interface/SimpleTransmission</type>
    <joint name="omnirob_right_lwr_1_joint">
      <hardwareInterface>PositionJointInterface</hardwareInterface>
      <hardwareInterface>EffortJointInterface</hardwareInterface>
    </joint>
    <actuator name="omnirob_right_lwr_1_motor">
      <mechanicalReduction>1</mechanicalReduction>
    </actuator>
  </transmission>
  <transmission name="omnirob_right_lwr_2_trans">
    <type>transmission_interface/SimpleTransmission</type>
    <joint name="omnirob_right_lwr_2_joint">
      <hardwareInterface>PositionJointInterface</hardwareInterface>
      <hardwareInterface>EffortJointInterface</hardwareInterface>
    </joint>
    <actuator name="omnirob_right_lwr_2_motor">
      <mechanicalReduction>1</mechanicalReduction>
    </actuator>
  </transmission>
  <transmission name="omnirob_right_lwr_3_trans">
    <type>transmission_interface/SimpleTransmission</type>
    <joint name="omnirob_right_lwr_3_joint">
      <hardwareInterface>PositionJointInterface</hardwareInterface>
      <hardwareInterface>EffortJointInterface</hardwareInterface>
    </joint>
    <actuator name="omnirob_right_lwr_3_motor">
      <mechanicalReduction>1</mechanicalReduction>
    </actuator>
  </transmission>
  <transmission name="omnirob_right_lwr_4_trans">
    <type>transmission_interface/SimpleTransmission</type>
    <joint name="omnirob_right_lwr_4_joint">
      <hardwareInterface>PositionJointInterface</hardwareInterface>
      <hardwareInterface>EffortJointInterface</hardwareInterface>
    </joint>
    <actuator name="omnirob_right_lwr_4_motor">
      <mechanicalReduction>1</mechanicalReduction>
    </actuator>
  </transmission>
  <transmission name="omnirob_right_lwr_5_trans">
    <type>transmission_interface/SimpleTransmission</type>
    <joint name="omnirob_right_lwr_5_joint">
      <hardwareInterface>PositionJointInterface</hardwareInterface>
      <hardwareInterface>EffortJointInterface</hardwareInterface>
    </joint>
    <actuator name="omnirob_right_lwr_5_motor">
      <mechanicalReduction>1</mechanicalReduction>
    </actuator>
  </transmission>
  <transmission name="omnirob_right_lwr_6_trans">
    <type>transmission_interface/SimpleTransmission</type>
    <joint name="omnirob_right_lwr_6_joint">
      <hardwareInterface>PositionJointInterface</hardwareInterface>
      <hardwareInterface>EffortJointInterface</hardwareInterface>
    </joint>
    <actuator name="omnirob_right_lwr_6_motor">
      <mechanicalReduction>1</mechanicalReduction>
    </actuator>
  </transmission>
  <link name="omnirob_kinect_front_link"/>
  <link name="omnirob_kinect_left_link"/>
  <link name="omnirob_kinect_right_link"/>
  <link name="omnirob_kinect_back_link"/>
  <!--<link name="$(arg name_prefix)tower">
    <visual>
      <geometry>        
        <mesh filename="package://ros_omnirob_description/meshes/OMNIROB_tower.dae" scale="1 1 1"/>
      </geometry>

      <origin rpy="0 0 0" xyz="0 0 0"/>
    </visual>
    
    <collision>
      <geometry>        
        <mesh filename="package://ros_omnirob_description/meshes/OMNIROB_tower.stl" scale="1 1 1"/>
      </geometry>
      <origin rpy="0 0 0" xyz="0 0 0"/>
    </collision>
  </link>-->
  <joint name="omnirob_base_x_joint" type="prismatic">
    <parent link="base_link"/>
    <child link="omnirob_base_x"/>
    <origin xyz="0 0 0"/>
    <axis xyz="1 0 0"/>
    <limit effort="1000.0" lower="-10.0" upper="10.0" velocity="0.5"/>
  </joint>
  <joint name="omnirob_base_y_joint" type="prismatic">
    <parent link="omnirob_base_x"/>
    <child link="omnirob_base_y"/>
    <origin xyz="0 0 0"/>
    <axis xyz="0 1 0"/>
    <limit effort="1000.0" lower="-10.0" upper="10.0" velocity="0.5"/>
  </joint>
  <joint name="omnirob_base_theta_joint" type="continuous">
    <parent link="omnirob_base_y"/>
    <child link="omnirob_platform"/>
    <origin xyz="0 0 0"/>
    <axis xyz="0 0 1"/>
    <limit effort="1000.0" velocity="0.5"/>
  </joint>
  <joint name="omnirob_base_connector_joint" type="fixed">
    <parent link="omnirob_platform"/>
    <child link="omnirob_connector"/>
    <origin xyz="0 0 0"/>
  </joint>
  <joint name="omnirob_left_lwr_base_joint" type="fixed">
    <parent link="omnirob_connector"/>
    <child link="omnirob_left_lwr_base"/>
    <origin rpy="1.047 0 3.1415" xyz="0.37 0.065 0.85"/>
  </joint>
  <joint name="omnirob_right_lwr_base_joint" type="fixed">
    <parent link="omnirob_connector"/>
    <child link="omnirob_right_lwr_base"/>
    <origin rpy="-1.047 0 3.1415" xyz="0.37 -0.065 0.85"/>
  </joint>
  <!--88x52x65 offsetx:17/2-->
  <joint name="omnirob_kinect_front_joint" type="fixed">
    <parent link="omnirob_platform"/>
    <child link="omnirob_kinect_front_link"/>
    <origin rpy="0 0.775 0" xyz="0.525 0 0.98"/>
  </joint>
  <joint name="omnirob_kinect_back_joint" type="fixed">
    <parent link="omnirob_platform"/>
    <child link="omnirob_kinect_back_link"/>
    <origin rpy="0 0.285 3.1415" xyz="-0.355 0 0.65"/>
  </joint>
  <joint name="omnirob_kinect_left_joint" type="fixed">
    <parent link="omnirob_platform"/>
    <child link="omnirob_kinect_left_link"/>
    <origin rpy="0 0 1.5708" xyz="0 0.26 0.65"/>
  </joint>
  <joint name="omnirob_kinect_right_joint" type="fixed">
    <parent link="omnirob_platform"/>
    <child link="omnirob_kinect_right_link"/>
    <origin rpy="0 0 -1.5708" xyz="0 -0.26 0.65"/>
  </joint>
  <!--<joint name="$(arg name_prefix)connector_tower_joint" type="fixed">
    <parent link="$(arg name_prefix)platform"/>
    <child link="$(arg name_prefix)tower"/>
    <origin xyz="0 0 1"/>
    <axis xyz="0 0 1"/>

  </joint>-->
</robot>

