<?xml version="1.0" ?>
<!-- =================================================================================== -->
<!-- |    This document was autogenerated by xacro from svh-standalone.urdf.xacro      | -->
<!-- |    EDITING THIS FILE BY HAND IS NOT RECOMMENDED                                 | -->
<!-- =================================================================================== -->
<robot name="svh" xmlns:xacro="http://www.ros.org/wiki/xacro">
  <link name="base_link"/>
  <!-- RIGHT HAND = 1, LEFT HAND = -1 -->
  <!-- BASE_LINE LINKS -->

  <joint name="base_x_joint" type="prismatic">
    <origin rpy="0 0 0" xyz="0 0 0"/>
    <axis xyz="1 0 0"/>
    <parent link="base_link"/>
    <child link="base_x_link"/>
    <limit effort="1000.0" lower="-1.0" upper="1.0" velocity="0.5"/>
  </joint>
  <joint name="base_y_joint" type="prismatic">
    <origin rpy="0 0 0" xyz="0 0 0"/>
    <axis xyz="0 1 0"/>
    <parent link="base_x_link"/>
    <child link="base_y_link"/>
    <limit effort="1000.0" lower="-1.0" upper="1.0" velocity="0.5"/>
  </joint>
  <joint name="base_z_joint" type="prismatic">
    <origin rpy="0 0 0" xyz="0 0 0"/>
    <axis xyz="0 0 1"/>
    <parent link="base_y_link"/>
    <child link="base_z_link"/>
    <limit effort="1000.0" lower="-1.0" upper="1.0" velocity="0.5"/>
  </joint>
  <joint name="base_roll_joint" type="continuous">
    <origin rpy="0 0 0" xyz="0 0 0"/>
    <axis xyz="0 0 1"/>
    <parent link="base_z_link"/>
    <child link="base_roll_link"/>
  </joint>
  <joint name="base_pitch_joint" type="continuous">
    <origin rpy="0 0 0" xyz="0 0 0"/>
    <axis xyz="1 0 0"/>
    <parent link="base_roll_link"/>
    <child link="base_pitch_link"/>
  </joint>
  <joint name="base_yaw_joint" type="continuous">
    <origin rpy="0 0 0" xyz="0 0 0"/>
    <axis xyz="0 1 0"/>
    <parent link="base_pitch_link"/>
    <child link="base_yaw_link"/>
  </joint>

  <link name="base_x_link"/>
  <link name="base_y_link"/>
  <link name="base_z_link"/>
  <link name="base_roll_link"/>
  <link name="base_pitch_link"/>
  <link name="base_yaw_link"/>

  <joint name="right_hand_base_joint" type="fixed">
    <origin rpy="0 0 0" xyz="0 0 0"/>
    <parent link="base_yaw_link"/>
    <child link="right_hand_base_link"/>
  </joint>
  <link name="right_hand_base_link">
    <origin rpy="0 0 0" xyz="0 0 0"/>
    <visual>
      <origin rpy="0 0 0" xyz="0 0 -0.032"/>
      <geometry>
        <mesh filename="package://schunk_svh_driver/description/meshes/base10.dae"/>
      </geometry>
    </visual>
    <collision>
      <origin rpy="0 0 0" xyz="0 0 -0.032"/>
      <geometry>
        <mesh filename="package://schunk_svh_driver/description/meshes/base10.dae"/>
      </geometry>
    </collision>
  </link>

  <!-- LENGTH NOT FOUND IN DATASHEET! GUESSED!!! -->
  <link name="right_hand_e1">
    <visual>
      <origin rpy="0 0 0" xyz="0 0.01313 0"/>
      <geometry>
        <mesh filename="package://schunk_svh_driver/description/meshes/h10.dae" scale="1.0 1 1"/>
      </geometry>
    </visual>
    <collision>
      <origin rpy="0 0 0" xyz="0 0.01313 0"/>
      <geometry>
        <mesh filename="package://schunk_svh_driver/description/meshes/h10.dae" scale="1.0 1 1"/>
      </geometry>
    </collision>
  </link>
  <!-- LENGTH NOT FOUND IN DATASHEET! GUESSED!!! -->
  <link name="right_hand_e2">
    <visual>
      <origin xyz="-0.0007 0 -0.01002"/>
      <geometry>
        <mesh filename="package://schunk_svh_driver/description/meshes/h11.dae" scale="1.0 1 1"/>
      </geometry>
    </visual>
    <collision>
      <origin xyz="-0.0007 0 -0.01002"/>
      <geometry>
        <mesh filename="package://schunk_svh_driver/description/meshes/h11.dae" scale="1.0 1 1"/>
      </geometry>
    </collision>
  </link>


  <!-- BASE_LINE JOINTS -->

  <joint name="right_hand_f4" type="fixed">
    <parent link="right_hand_base_link"/>
    <child link="right_hand_e1"/>
    <origin rpy="0 0 0" xyz="0 -0.01313 0"/>
  </joint>
  <joint name="right_hand_j5" type="revolute">
    <parent link="right_hand_e1"/>
    <child link="right_hand_e2"/>
    <limit effort="1000.0" lower="0.0" upper="0.98786" velocity="1"/>
    <origin rpy="0 0 0" xyz="0.0184 0.006 0.0375"/>
    <axis xyz="0 0 1.0"/>
  </joint>

</robot>
