<?xml version="1.0" ?>
<!-- =================================================================================== -->
<!-- |    This document was autogenerated by xacro from hollie.urdf.xacro              | -->
<!-- |    EDITING THIS FILE BY HAND IS NOT RECOMMENDED                                 | -->
<!-- =================================================================================== -->
<robot name="HoLLiE" xmlns:controller="http://playerstage.sourceforge.net/gazebo/xmlschema/#controller" xmlns:interface="http://playerstage.sourceforge.net/gazebo/xmlschema/#interface" xmlns:sensor="http://playerstage.sourceforge.net/gazebo/xmlschema/#sensor" xmlns:xacro="http://www.ros.org/wiki/xacro">
  <!--  blue and lightgrey are switched by schunk in their file for the schunk powerball arm -->
  <!-- Required arguments: 
       name_prefix : a prefix for all the frames as workaround for the tf_prefix
       r1 : a rgb color
       g1 : a rgb color
       b1 : a rgb color
       r2 : a rgb color
       g2 : a rgb color
       b2 : a rgb color 
  -->
  <material name="Schunk/Blue">
    <color rgba="0.0 0.0 0.0 1"/>
  </material>
  <material name="Schunk/LightGrey">
    <color rgba="0 0.0 0.0 1"/>
  </material>
  <link name="base_link"/>
  <link name="hollie_plain_base_x"/>
  <link name="hollie_plain_base_y"/>
  <link name="hollie_plain_base_theta">
    <visual>
      <geometry>
        <mesh filename="package://ros_hollie/hollie_description/meshes/plattform_vereinfacht.stl" scale="0.001 0.001 0.001"/>
      </geometry>
      <origin rpy="0 0 0" xyz="0 0 0"/>
      <material name="Schunk/LightGrey"/>
    </visual>
    <collision>
      <geometry>
        <mesh filename="package://ros_hollie/hollie_description/meshes/plattform_vereinfacht.stl" scale="0.001 0.001 0.001"/>
      </geometry>
      <origin rpy="0 0 0" xyz="0 0 0"/>
      <material name="Schunk/LightGrey"/>
    </collision>
  </link>
  <link name="hollie_plain_lower_torso_link">
    <visual>
      <geometry>
        <mesh filename="package://ros_hollie/hollie_description/meshes/unterkoerper_vereinfacht.stl" scale="0.001 0.001 0.001"/>
      </geometry>
      <origin rpy="0 0 0" xyz="0 0 0"/>
      <material name="Schunk/Blue"/>
    </visual>
    <collision>
      <geometry>
        <mesh filename="package://ros_hollie/hollie_description/meshes/unterkoerper_vereinfacht.stl" scale="0.001 0.001 0.001"/>
      </geometry>
      <origin rpy="0 0 0" xyz="0 0 0"/>
    </collision>
  </link>
  <link name="hollie_plain_upper_torso_link">
    <visual>
      <geometry>
        <mesh filename="package://ros_hollie/hollie_description/meshes/Oberkoerper_unvollstaendig.stl" scale="0.001 0.001 0.001"/>
      </geometry>
      <origin rpy="0 0 0" xyz="0 0 0"/>
      <material name="Schunk/Blue"/>
    </visual>
    <collision>
      <origin rpy="0 0 0" xyz="0 0 0"/>
      <geometry>
        <mesh filename="package://ros_hollie/hollie_description/meshes/Oberkoerper_unvollstaendig.stl" scale="0.001 0.001 0.001"/>
      </geometry>
    </collision>
  </link>
  <link name="hollie_plain_back">
    <visual>
      <geometry>
        <mesh filename="package://ros_hollie/hollie_description/meshes/huelle_ruecken.stl" scale="0.001 0.001 0.001"/>
      </geometry>
      <origin rpy="0 0 0" xyz="0 0 0"/>
      <material name="Schunk/Blue"/>
    </visual>
    <collision>
      <geometry>
        <mesh filename="package://ros_hollie/hollie_description/meshes/huelle_ruecken.stl" scale="0.001 0.001 0.001"/>
      </geometry>
      <origin rpy="0 0 0" xyz="0 0 0"/>
    </collision>
  </link>
  <link name="hollie_plain_arm_base">
    <visual>
      <geometry>
        <mesh filename="package://ros_hollie/hollie_description/meshes/arm_verbinder_mit_stahlrohr.stl" scale="0.001 0.001 0.001"/>
      </geometry>
      <origin rpy="0 0 0" xyz="0 0 0"/>
      <material name="Schunk/Blue"/>
    </visual>
    <collision>
      <geometry>
        <mesh filename="package://ros_hollie/hollie_description/meshes/arm_verbinder_mit_stahlrohr.stl" scale="0.001 0.001 0.001"/>
      </geometry>
      <origin rpy="0 0 0" xyz="0 0 0"/>
    </collision>
  </link>
  <link name="hollie_plain_arm_base_mimic_0_link"/>
  <link name="hollie_plain_arm_base_mimic_1_link"/>
  <link name="hollie_plain_neck">
    <visual>
      <geometry>
        <mesh filename="package://ros_hollie/hollie_description/meshes/hals_vereinfacht.stl" scale="0.001 0.001 0.001"/>
      </geometry>
      <origin rpy="0 0 0" xyz="0 0 0"/>
      <material name="Schunk/Blue"/>
    </visual>
    <collision>
      <geometry>
        <mesh filename="package://ros_hollie/hollie_description/meshes/hals_vereinfacht.stl" scale="0.001 0.001 0.001"/>
      </geometry>
      <origin rpy="0 0 0" xyz="0 0 0"/>
    </collision>
  </link>
  <link name="hollie_plain_head">
    <visual>
      <geometry>
        <mesh filename="package://ros_hollie/hollie_description/meshes/kopf_version_2.stl" scale="0.001 0.001 0.001"/>
      </geometry>
      <origin rpy="0 0 0" xyz="0 0 0"/>
      <material name="Schunk/Blue"/>
    </visual>
    <collision>
      <geometry>
        <mesh filename="package://ros_hollie/hollie_description/meshes/kopf_version_2.stl" scale="0.001 0.001 0.001"/>
      </geometry>
      <origin rpy="0 0 0" xyz="0 0 0"/>
    </collision>
  </link>
  <link name="hollie_plain_camera_link">
    <origin rpy="0 0 0" xyz="0 0 0"/>
  </link>
  <link name="hollie_plain_left_arm_calibration">
    <origin rpy="0 0 0" xyz="0 0 0"/>
  </link>
  <link name="hollie_plain_right_arm_calibration">
    <origin rpy="0 0 0" xyz="0 0 0"/>
  </link>
  <joint name="hollie_plain_base_x_joint" type="prismatic">
    <parent link="base_link"/>
    <child link="hollie_plain_base_x"/>
    <origin xyz="0 0 0"/>
    <axis xyz="1 0 0"/>
    <limit effort="1000.0" lower="-10.0" upper="10.0" velocity="0.5"/>
  </joint>
  <joint name="hollie_plain_base_y_joint" type="prismatic">
    <parent link="hollie_plain_base_x"/>
    <child link="hollie_plain_base_y"/>
    <origin xyz="0 0 0"/>
    <axis xyz="0 1 0"/>
    <limit effort="1000.0" lower="-10.0" upper="10.0" velocity="0.5"/>
  </joint>
  <joint name="hollie_plain_base_theta_joint" type="continuous">
    <parent link="hollie_plain_base_y"/>
    <child link="hollie_plain_base_theta"/>
    <origin xyz="0 0 0"/>
    <axis xyz="0 0 1"/>
    <limit effort="1000.0" velocity="0.5"/>
  </joint>
  <joint name="hollie_plain_lower_torso" type="revolute">
    <parent link="hollie_plain_base_theta"/>
    <child link="hollie_plain_lower_torso_link"/>
    <origin xyz="0 0 0.34"/>
    <axis xyz="0 1 0"/>
    <!--   50 degree = 0.87266   -->
    <limit effort="1000.0" lower="-0.87266" upper="0.87266" velocity="0.5"/>
  </joint>
  <joint name="hollie_plain_upper_torso" type="revolute">
    <parent link="hollie_plain_lower_torso_link"/>
    <child link="hollie_plain_upper_torso_link"/>
    <origin xyz="0 0 0.5"/>
    <axis xyz="0 1 0"/>
    <!--   80 degree = 1.39626   -->
    <limit effort="1000.0" lower="0.0" upper="1.39626" velocity="0.5"/>
  </joint>
  <joint name="hollie_plain_upper_torso_to_back" type="fixed">
    <parent link="hollie_plain_upper_torso_link"/>
    <child link="hollie_plain_back"/>
    <origin xyz="0 0 -0.875"/>
  </joint>
  <joint name="hollie_plain_upper_torso_to_arm_base" type="fixed">
    <parent link="hollie_plain_upper_torso_link"/>
    <child link="hollie_plain_arm_base_mimic_0_link"/>
    <origin rpy="0 0 0" xyz="0 0 0.4"/>
  </joint>
  <joint name="hollie_plain_arm_base_mimic_lower_torso_joint" type="revolute">
    <parent link="hollie_plain_arm_base_mimic_0_link"/>
    <child link="hollie_plain_arm_base_mimic_1_link"/>
    <mimic joint="hollie_plain_lower_torso" multiplier="-1.0" offset="0.0"/>
    <axis xyz="0 1 0"/>
    <limit effort="1000.0" lower="-0.87266" upper="0.87266" velocity="0.5"/>
  </joint>
  <joint name="hollie_plain_arm_base_mimic_upper_torso_joint" type="revolute">
    <parent link="hollie_plain_arm_base_mimic_1_link"/>
    <child link="hollie_plain_arm_base"/>
    <mimic joint="hollie_plain_upper_torso" multiplier="-1.0" offset="0.0"/>
    <axis xyz="0 1 0"/>
    <limit effort="1000.0" lower="-1.39626" upper="0.0" velocity="0.5"/>
  </joint>
  <joint name="hollie_plain_neck_pitch" type="revolute">
    <parent link="hollie_plain_arm_base"/>
    <child link="hollie_plain_neck"/>
    <origin rpy="0 0 0" xyz="-0.0 -0.0 0.08"/>
    <axis xyz="0 1 0"/>
    <limit effort="1000.0" lower="-1.57075" upper="1.57075" velocity="0.5"/>
  </joint>
  <joint name="hollie_plain_neck_yaw" type="revolute">
    <parent link="hollie_plain_neck"/>
    <child link="hollie_plain_head"/>
    <origin rpy="0 0 0" xyz="0 0 0"/>
    <axis xyz="0 0 1"/>
    <limit effort="1000.0" lower="-1.57075" upper="1.57075" velocity="0.5"/>
  </joint>
  <joint name="hollie_plain_head_to_camera" type="fixed">
    <parent link="hollie_plain_head"/>
    <child link="hollie_plain_camera_link"/>
    <origin rpy="0 0 0" xyz="0 0 0.13"/>
  </joint>
  <joint name="hollie_plain_left_arm_calibration_joint" type="fixed">
    <parent link="hollie_plain_arm_base"/>
    <child link="hollie_plain_left_arm_calibration"/>
    <origin rpy="0 0 0" xyz="0 0 0"/>
  </joint>
  <joint name="hollie_plain_right_arm_calibration_joint" type="fixed">
    <parent link="hollie_plain_arm_base"/>
    <child link="hollie_plain_right_arm_calibration"/>
    <origin rpy="0 0 0" xyz="0 0 0"/>
  </joint>
  <joint name="hollie_plain_right_arm_0_joint" type="fixed">
    <origin rpy="-1.57075 0 3.1415" xyz="0 -0.1425 0"/>
    <parent link="hollie_plain_right_arm_calibration"/>
    <child link="hollie_plain_right_arm_0_link"/>
  </joint>
  <link name="hollie_plain_right_arm_0_link">
    <inertial>
      <origin rpy="0 0 0" xyz="0 0 0"/>
      <mass value="0.29364"/>
      <inertia ixx="0.01" ixy="0" ixz="0" iyy="0.01" iyz="0" izz="0.01"/>
    </inertial>
    <visual>
      <origin rpy="0 0 0" xyz="0 0 0"/>
      <geometry>
        <mesh filename="package://schunk_description/meshes/lwa4p/arm_0_link.dae"/>
      </geometry>
      <!-- <material name="Schunk/LightGrey" /> -->
    </visual>
    <collision>
      <origin rpy="0 0 0" xyz="0 0 0"/>
      <geometry>
        <mesh filename="package://schunk_description/meshes/lwa4p/arm_0_link.stl"/>
      </geometry>
    </collision>
  </link>
  <joint name="hollie_plain_right_arm_1_joint" type="revolute">
    <origin rpy="0 0 0" xyz="0 0 0.11"/>
    <parent link="hollie_plain_right_arm_0_link"/>
    <child link="hollie_plain_right_arm_1_link"/>
    <axis xyz="0 0 1"/>
    <calibration rising="2.1"/>
    <dynamics damping="10"/>
    <limit effort="370" lower="-6.2831853" upper="6.2831853" velocity="2.0"/>
    <safety_controller k_position="20" k_velocity="50" soft_lower_limit="-6.2731853" soft_upper_limit="6.2731853"/>
  </joint>
  <link name="hollie_plain_right_arm_1_link">
    <inertial>
      <origin rpy="0 0 0" xyz="0 0 0"/>
      <mass value="0.29364"/>
      <inertia ixx="0.01" ixy="0" ixz="0" iyy="0.01" iyz="0" izz="0.01"/>
    </inertial>
    <visual>
      <origin rpy="0 0 0" xyz="0 0 0"/>
      <geometry>
        <mesh filename="package://schunk_description/meshes/lwa4p/arm_1_link.dae"/>
      </geometry>
      <!-- <material name="Schunk/Blue" /> -->
    </visual>
    <collision>
      <origin rpy="0 0 0" xyz="0 0 0"/>
      <geometry>
        <mesh filename="package://schunk_description/meshes/lwa4p/arm_1_link.stl"/>
      </geometry>
    </collision>
  </link>
  <joint name="hollie_plain_right_arm_2_joint" type="revolute">
    <origin rpy="1.5708 0 0" xyz="0 0 0"/>
    <parent link="hollie_plain_right_arm_1_link"/>
    <child link="hollie_plain_right_arm_2_link"/>
    <axis xyz="0 0 1"/>
    <calibration rising="2.1"/>
    <dynamics damping="10"/>
    <limit effort="370" lower="-2.0943951" upper="2.0943951" velocity="2.0"/>
    <safety_controller k_position="20" k_velocity="50" soft_lower_limit="-2.0843" soft_upper_limit="2.0843"/>
  </joint>
  <link name="hollie_plain_right_arm_2_link">
    <inertial>
      <origin rpy="0 0 0" xyz="0 0 0"/>
      <mass value="1.68311"/>
      <inertia ixx="0.03" ixy="0" ixz="0" iyy="0.03" iyz="0" izz="0.03"/>
    </inertial>
    <visual>
      <origin rpy="0 0 0" xyz="0 0 0"/>
      <geometry>
        <mesh filename="package://schunk_description/meshes/lwa4p/arm_2_link.dae"/>
      </geometry>
      <!-- <material name="Schunk/LightGrey" /> -->
    </visual>
    <collision>
      <origin rpy="0 0 0" xyz="0 0 0"/>
      <geometry>
        <mesh filename="package://schunk_description/meshes/lwa4p/arm_2_link.stl"/>
      </geometry>
    </collision>
  </link>
  <joint name="hollie_plain_right_arm_3_joint" type="revolute">
    <origin rpy="0 3.14159 0" xyz="0 0.350 0"/>
    <parent link="hollie_plain_right_arm_2_link"/>
    <child link="hollie_plain_right_arm_3_link"/>
    <axis xyz="0 0 1"/>
    <calibration rising="2.1"/>
    <dynamics damping="5"/>
    <limit effort="176" lower="-6.2831853" upper="6.2831853" velocity="2.0"/>
    <safety_controller k_position="20" k_velocity="25" soft_lower_limit="-6.2731853" soft_upper_limit="6.2731853"/>
  </joint>
  <link name="hollie_plain_right_arm_3_link">
    <inertial>
      <origin rpy="0 0 0" xyz="0 0 0"/>
      <mass value="2.1"/>
      <inertia ixx="0.03" ixy="0" ixz="0" iyy="0.03" iyz="0" izz="0.03"/>
    </inertial>
    <visual>
      <origin rpy="0 0 0" xyz="0 0 0"/>
      <geometry>
        <mesh filename="package://schunk_description/meshes/lwa4p/arm_3_link.dae"/>
      </geometry>
      <!-- <material name="Schunk/Blue" /> -->
    </visual>
    <collision>
      <origin rpy="0 0 0" xyz="0 0 0"/>
      <geometry>
        <mesh filename="package://schunk_description/meshes/lwa4p/arm_3_link.stl"/>
      </geometry>
    </collision>
  </link>
  <joint name="hollie_plain_right_arm_4_joint" type="revolute">
    <origin rpy="-1.5708 3.14159 0" xyz="0 0 0"/>
    <parent link="hollie_plain_right_arm_3_link"/>
    <child link="hollie_plain_right_arm_4_link"/>
    <axis xyz="0 0 1"/>
    <calibration rising="2.1"/>
    <dynamics damping="5"/>
    <limit effort="176" lower="-2.0943951" upper="2.0943951" velocity="2.0"/>
    <safety_controller k_position="20" k_velocity="25" soft_lower_limit="-2.0843951" soft_upper_limit="2.0843951"/>
  </joint>
  <link name="hollie_plain_right_arm_4_link">
    <inertial>
      <origin rpy="0 0 0" xyz="0 0 0"/>
      <mass value="1.68311"/>
      <inertia ixx="0.03" ixy="0" ixz="0" iyy="0.03" iyz="0" izz="0.03"/>
    </inertial>
    <visual>
      <origin rpy="0 0 0" xyz="0 0 0"/>
      <geometry>
        <mesh filename="package://schunk_description/meshes/lwa4p/arm_4_link.dae"/>
      </geometry>
      <!-- <material name="Schunk/LightGrey" /> -->
    </visual>
    <collision>
      <origin rpy="0 0 0" xyz="0 0 0"/>
      <geometry>
        <mesh filename="package://schunk_description/meshes/lwa4p/arm_4_link.stl"/>
      </geometry>
    </collision>
  </link>
  <joint name="hollie_plain_right_arm_5_joint" type="revolute">
    <origin rpy="1.5708 0 3.14159" xyz="0 0.005263 0.365"/>
    <parent link="hollie_plain_right_arm_4_link"/>
    <child link="hollie_plain_right_arm_5_link"/>
    <axis xyz="0 0 1"/>
    <calibration rising="2.1"/>
    <dynamics damping="5"/>
    <limit effort="41.6" lower="-6.2831853" upper="6.2831853" velocity="2.0"/>
    <safety_controller k_position="20" k_velocity="25" soft_lower_limit="-6.2731853" soft_upper_limit="6.2731853"/>
  </joint>
  <link name="hollie_plain_right_arm_5_link">
    <inertial>
      <origin rpy="0 0 0" xyz="0 0 0"/>
      <mass value="0.807"/>
      <inertia ixx="0.03" ixy="0" ixz="0" iyy="0.03" iyz="0" izz="0.03"/>
    </inertial>
    <visual>
      <origin rpy="0 0 0" xyz="0 0 0"/>
      <geometry>
        <mesh filename="package://schunk_description/meshes/lwa4p/arm_5_link.dae"/>
      </geometry>
      <!-- <material name="Schunk/Blue" /> -->
    </visual>
    <collision>
      <origin rpy="0 0 0" xyz="0 0 0"/>
      <geometry>
        <mesh filename="package://schunk_description/meshes/lwa4p/arm_5_link.stl"/>
      </geometry>
    </collision>
  </link>
  <joint name="hollie_plain_right_arm_6_joint" type="revolute">
    <origin rpy="-1.5708 0 0" xyz="0 0 0"/>
    <parent link="hollie_plain_right_arm_5_link"/>
    <child link="hollie_plain_right_arm_6_link"/>
    <axis xyz="0 0 1"/>
    <calibration rising="2.1"/>
    <dynamics damping="5"/>
    <limit effort="20.1" lower="-2.0943951" upper="2.0943951" velocity="2.0"/>
    <safety_controller k_position="20" k_velocity="25" soft_lower_limit="-2.0843951" soft_upper_limit="2.0843951"/>
  </joint>
  <link name="hollie_plain_right_arm_6_link">
    <inertial>
      <origin rpy="0 0 0" xyz="0 0 0"/>
      <mass value="0.819"/>
      <inertia ixx="0.01" ixy="0" ixz="0" iyy="0.01" iyz="0" izz="0.01"/>
    </inertial>
    <visual>
      <origin rpy="0 0 0" xyz="0 0 0"/>
      <geometry>
        <mesh filename="package://schunk_description/meshes/lwa4p/arm_6_link.dae"/>
      </geometry>
      <!-- <material name="Schunk/LightGrey" /> -->
    </visual>
    <collision>
      <origin rpy="0 0 0" xyz="0 0 0"/>
      <geometry>
        <mesh filename="package://schunk_description/meshes/lwa4p/arm_6_link.stl"/>
      </geometry>
    </collision>
  </link>
  <gazebo reference="hollie_plain_right_arm_0_link">
    <material value="Schunk/LightGrey"/>
    <turnGravityOff>false</turnGravityOff>
    <selfCollide>true</selfCollide>
  </gazebo>
  <gazebo reference="hollie_plain_right_arm_1_link">
    <material value="Schunk/Blue"/>
    <turnGravityOff>false</turnGravityOff>
    <selfCollide>true</selfCollide>
  </gazebo>
  <gazebo reference="hollie_plain_right_arm_2_link">
    <material value="Schunk/LightGrey"/>
    <turnGravityOff>false</turnGravityOff>
    <selfCollide>true</selfCollide>
  </gazebo>
  <gazebo reference="hollie_plain_right_arm_3_link">
    <material value="Schunk/Blue"/>
    <turnGravityOff>false</turnGravityOff>
    <selfCollide>true</selfCollide>
  </gazebo>
  <gazebo reference="hollie_plain_right_arm_4_link">
    <material value="Schunk/LightGrey"/>
    <turnGravityOff>false</turnGravityOff>
    <selfCollide>true</selfCollide>
  </gazebo>
  <gazebo reference="hollie_plain_right_arm_5_link">
    <material value="Schunk/Blue"/>
    <turnGravityOff>false</turnGravityOff>
    <selfCollide>true</selfCollide>
  </gazebo>
  <gazebo reference="hollie_plain_right_arm_6_link">
    <material value="Schunk/LightGrey"/>
    <turnGravityOff>false</turnGravityOff>
    <selfCollide>true</selfCollide>
  </gazebo>
  <transmission name="hollie_plain_right_arm_1_trans">
    <type>transmission_interface/SimpleTransmission</type>
    <joint name="hollie_plain_right_arm_1_joint"/>
    <actuator name="hollie_plain_right_arm_1_motor">
      <hardwareInterface>EffortJointInterface</hardwareInterface>
      <mechanicalReduction>1</mechanicalReduction>
    </actuator>
  </transmission>
  <transmission name="hollie_plain_right_arm_2_trans">
    <type>transmission_interface/SimpleTransmission</type>
    <joint name="hollie_plain_right_arm_2_joint"/>
    <actuator name="hollie_plain_right_arm_2_motor">
      <hardwareInterface>EffortJointInterface</hardwareInterface>
      <mechanicalReduction>1</mechanicalReduction>
    </actuator>
  </transmission>
  <transmission name="hollie_plain_right_arm_3_trans">
    <type>transmission_interface/SimpleTransmission</type>
    <joint name="hollie_plain_right_arm_3_joint"/>
    <actuator name="hollie_plain_right_arm_3_motor">
      <hardwareInterface>EffortJointInterface</hardwareInterface>
      <mechanicalReduction>1</mechanicalReduction>
    </actuator>
  </transmission>
  <transmission name="hollie_plain_right_arm_4_trans">
    <type>transmission_interface/SimpleTransmission</type>
    <joint name="hollie_plain_right_arm_4_joint"/>
    <actuator name="hollie_plain_right_arm_4_motor">
      <hardwareInterface>EffortJointInterface</hardwareInterface>
      <mechanicalReduction>1</mechanicalReduction>
    </actuator>
  </transmission>
  <transmission name="hollie_plain_right_arm_5_trans">
    <type>transmission_interface/SimpleTransmission</type>
    <joint name="hollie_plain_right_arm_5_joint"/>
    <actuator name="hollie_plain_right_arm_5_motor">
      <hardwareInterface>EffortJointInterface</hardwareInterface>
      <mechanicalReduction>1</mechanicalReduction>
    </actuator>
  </transmission>
  <transmission name="hollie_plain_right_arm_6_trans">
    <type>transmission_interface/SimpleTransmission</type>
    <joint name="hollie_plain_right_arm_6_joint"/>
    <actuator name="hollie_plain_right_arm_6_motor">
      <hardwareInterface>EffortJointInterface</hardwareInterface>
      <mechanicalReduction>1</mechanicalReduction>
    </actuator>
  </transmission>
  <joint name="hollie_plain_right_hand_base_joint" type="fixed">
    <origin rpy="0 0 0" xyz="0 0 0.1"/>
    <parent link="hollie_plain_right_arm_6_link"/>
    <child link="hollie_plain_right_hand_base_link"/>
  </joint>
  <link name="hollie_plain_right_hand_base_link">
    <origin rpy="0 0 0" xyz="0 0 0.1"/>
    <visual>
      <origin rpy="0 0 0" xyz="0 0 -0.032"/>
      <geometry>
        <mesh filename="package://schunk_svh_driver/description/meshes/base10.dae"/>
      </geometry>
    </visual>
    <collision>
      <origin rpy="0 0 0" xyz="0 0 -0.032"/>
      <geometry>
        <mesh filename="package://schunk_svh_driver/description/meshes/base10.dae"/>
      </geometry>
    </collision>
  </link>
  <link name="hollie_plain_right_hand_d">
    <!-- <visual> -->
    <!-- 	<geometry> -->
    <!-- 	  <cylinder length="0.110" radius="${cyl_radius}" /> -->
    <!-- 	</geometry> -->
    <!-- 	<material name="${name}_green" /> -->
    <!-- </visual> -->
  </link>
  <link name="hollie_plain_right_hand_h">
    <!-- <visual> -->
    <!-- 	<origin rpy="0 1.571 0" xyz="${side*(-0.0125)} 0 0.0825" /> -->
    <!-- 	<geometry> -->
    <!-- 	  <cylinder length="0.025" radius="${cyl_radius}" /> -->
    <!-- 	</geometry> -->
    <!-- 	<material name="${name}_green" /> -->
    <!-- </visual> -->
  </link>
  <link name="hollie_plain_right_hand_d2">
    <!-- <visual> -->
    <!-- 	<origin rpy="0 0 0" xyz="${side*(-0.025)} 0 0.09625" /> -->
    <!-- 	<geometry> -->
    <!-- 	  <cylinder length="0.0275" radius="${cyl_radius}" /> -->
    <!-- 	</geometry> -->
    <!-- 	<material name="${name}_green" /> -->
    <!-- </visual> -->
  </link>
  <link name="hollie_plain_right_hand_e1">
    <visual>
      <origin rpy="0 0 0" xyz="0 0.01313 0"/>
      <geometry>
        <mesh filename="package://schunk_svh_driver/description/meshes/h10.dae" scale="1.0 1 1"/>
      </geometry>
    </visual>
    <collision>
      <origin rpy="0 0 0" xyz="0 0.01313 0"/>
      <geometry>
        <mesh filename="package://schunk_svh_driver/description/meshes/h10.dae" scale="1.0 1 1"/>
      </geometry>
    </collision>
  </link>
  <link name="hollie_plain_right_hand_e2">
    <visual>
      <origin xyz="-0.0007 0 -0.01002"/>
      <geometry>
        <mesh filename="package://schunk_svh_driver/description/meshes/h11.dae" scale="1.0 1 1"/>
      </geometry>
    </visual>
    <collision>
      <origin xyz="-0.0007 0 -0.01002"/>
      <geometry>
        <mesh filename="package://schunk_svh_driver/description/meshes/h11.dae" scale="1.0 1 1"/>
      </geometry>
    </collision>
  </link>
  <link name="hollie_plain_right_hand_e3">
    <!-- <visual> -->
    <!-- 	<origin rpy="0 0 0" xyz="${side*(0.0175)} 0 0.015" /> -->
    <!-- 	<geometry> -->
    <!-- 	  <cylinder length="0.03" radius="${cyl_radius}" /> -->
    <!-- 	</geometry> -->
    <!-- 	<material name="green" /> -->
    <!-- </visual> -->
  </link>
  <link name="hollie_plain_right_hand_e">
    </link>
  <link name="hollie_plain_right_hand_e4">
    <!-- <visual> -->
    <!-- 	<origin rpy="0 0 0" xyz="${side*(0.02825)} 0 0.043" /> -->
    <!-- 	<geometry> -->
    <!-- 	  <cylinder length="0.026" radius="${cyl_radius}" /> -->
    <!-- 	</geometry> -->
    <!-- 	<material name="green" /> -->
    <!-- </visual> -->
  </link>
  <link name="hollie_plain_right_hand_e5">
    <!-- <visual> -->
    <!-- 	<origin rpy="0 0 0" xyz="${side*(0.00675)} 0 0.04775" /> -->
    <!-- 	<geometry> -->
    <!-- 	  <cylinder length="0.0355" radius="${cyl_radius}" /> -->
    <!-- 	</geometry> -->
    <!-- 	<material name="green" /> -->
    <!-- </visual> -->
  </link>
  <link name="hollie_plain_right_hand_z">
    <visual>
      <origin xyz="0 0 0.02442"/>
      <geometry>
        <mesh filename="package://schunk_svh_driver/description/meshes/d10.dae" scale="1 1.0 1"/>
      </geometry>
    </visual>
    <collision>
      <origin xyz="0 0 0.02442"/>
      <geometry>
        <mesh filename="package://schunk_svh_driver/description/meshes/d10.dae" scale="1 1.0 1"/>
      </geometry>
    </collision>
  </link>
  <link name="hollie_plain_right_hand_virtual_a"/>
  <link name="hollie_plain_right_hand_a">
    <visual>
      <geometry>
        <mesh filename="package://schunk_svh_driver/description/meshes/d11.dae" scale="1 1.0 1.0"/>
      </geometry>
    </visual>
    <collision>
      <geometry>
        <mesh filename="package://schunk_svh_driver/description/meshes/d11.dae" scale="1 1.0 1.0"/>
      </geometry>
    </collision>
  </link>
  <link name="hollie_plain_right_hand_b">
    <visual>
      <geometry>
        <mesh filename="package://schunk_svh_driver/description/meshes/d12.dae" scale="1 1.0 1.0"/>
      </geometry>
    </visual>
    <collision>
      <geometry>
        <mesh filename="package://schunk_svh_driver/description/meshes/d12.dae" scale="1 1.0 1.0"/>
      </geometry>
    </collision>
  </link>
  <link name="hollie_plain_right_hand_c">
    <visual>
      <geometry>
        <mesh filename="package://schunk_svh_driver/description/meshes/d13.dae" scale="1 1.0 1.0"/>
      </geometry>
    </visual>
    <collision>
      <geometry>
        <mesh filename="package://schunk_svh_driver/description/meshes/d13.dae" scale="1 1.0 1.0"/>
      </geometry>
    </collision>
  </link>
  <link name="hollie_plain_right_hand_virtual_l">
    <visual>
      <origin xyz="0 0 0.01321"/>
      <geometry>
        <mesh filename="package://schunk_svh_driver/description/meshes/f10.dae"/>
      </geometry>
    </visual>
    <collision>
      <origin xyz="0 0 0.01321"/>
      <geometry>
        <mesh filename="package://schunk_svh_driver/description/meshes/f10.dae"/>
      </geometry>
    </collision>
  </link>
  <link name="hollie_plain_right_hand_l">
    <visual>
      <geometry>
        <mesh filename="package://schunk_svh_driver/description/meshes/f11.dae"/>
      </geometry>
    </visual>
    <collision>
      <geometry>
        <mesh filename="package://schunk_svh_driver/description/meshes/f11.dae"/>
      </geometry>
    </collision>
  </link>
  <link name="hollie_plain_right_hand_p">
    <visual>
      <geometry>
        <mesh filename="package://schunk_svh_driver/description/meshes/f12.dae"/>
      </geometry>
    </visual>
    <collision>
      <geometry>
        <mesh filename="package://schunk_svh_driver/description/meshes/f12.dae"/>
      </geometry>
    </collision>
  </link>
  <link name="hollie_plain_right_hand_t">
    <visual>
      <geometry>
        <mesh filename="package://schunk_svh_driver/description/meshes/f13.dae"/>
      </geometry>
    </visual>
    <collision>
      <geometry>
        <mesh filename="package://schunk_svh_driver/description/meshes/f13.dae"/>
      </geometry>
    </collision>
  </link>
  <link name="hollie_plain_right_hand_virtual_k">
    <visual>
      <origin xyz="0 0 0.01321"/>
      <geometry>
        <mesh filename="package://schunk_svh_driver/description/meshes/f20.dae"/>
      </geometry>
    </visual>
    <collision>
      <origin xyz="0 0 0.01321"/>
      <geometry>
        <mesh filename="package://schunk_svh_driver/description/meshes/f20.dae"/>
      </geometry>
    </collision>
  </link>
  <link name="hollie_plain_right_hand_k">
    <visual>
      <geometry>
        <mesh filename="package://schunk_svh_driver/description/meshes/f21.dae"/>
      </geometry>
    </visual>
    <collision>
      <geometry>
        <mesh filename="package://schunk_svh_driver/description/meshes/f21.dae"/>
      </geometry>
    </collision>
  </link>
  <link name="hollie_plain_right_hand_o">
    <visual>
      <geometry>
        <mesh filename="package://schunk_svh_driver/description/meshes/f22.dae"/>
      </geometry>
    </visual>
    <collision>
      <geometry>
        <mesh filename="package://schunk_svh_driver/description/meshes/f22.dae"/>
      </geometry>
    </collision>
  </link>
  <link name="hollie_plain_right_hand_s">
    <visual>
      <geometry>
        <mesh filename="package://schunk_svh_driver/description/meshes/f23.dae"/>
      </geometry>
    </visual>
    <collision>
      <geometry>
        <mesh filename="package://schunk_svh_driver/description/meshes/f23.dae"/>
      </geometry>
    </collision>
  </link>
  <link name="hollie_plain_right_hand_virtual_j">
    <visual>
      <origin xyz="0 0 -0.01321"/>
      <geometry>
        <mesh filename="package://schunk_svh_driver/description/meshes/f30.dae"/>
      </geometry>
    </visual>
    <collision>
      <origin xyz="0 0 -0.01321"/>
      <geometry>
        <mesh filename="package://schunk_svh_driver/description/meshes/f30.dae"/>
      </geometry>
    </collision>
  </link>
  <link name="hollie_plain_right_hand_j">
    <visual>
      <geometry>
        <mesh filename="package://schunk_svh_driver/description/meshes/f31.dae"/>
      </geometry>
    </visual>
    <collision>
      <geometry>
        <mesh filename="package://schunk_svh_driver/description/meshes/f31.dae"/>
      </geometry>
    </collision>
  </link>
  <link name="hollie_plain_right_hand_n">
    <visual>
      <geometry>
        <mesh filename="package://schunk_svh_driver/description/meshes/f32.dae"/>
      </geometry>
    </visual>
    <collision>
      <geometry>
        <mesh filename="package://schunk_svh_driver/description/meshes/f32.dae"/>
      </geometry>
    </collision>
  </link>
  <link name="hollie_plain_right_hand_r">
    <visual>
      <geometry>
        <mesh filename="package://schunk_svh_driver/description/meshes/f33.dae"/>
      </geometry>
    </visual>
    <collision>
      <geometry>
        <mesh filename="package://schunk_svh_driver/description/meshes/f33.dae"/>
      </geometry>
    </collision>
  </link>
  <link name="hollie_plain_right_hand_virtual_i">
    <visual>
      <origin xyz="0 0 -0.01321"/>
      <geometry>
        <mesh filename="package://schunk_svh_driver/description/meshes/f40.dae"/>
      </geometry>
    </visual>
    <collision>
      <origin xyz="0 0 -0.01321"/>
      <geometry>
        <mesh filename="package://schunk_svh_driver/description/meshes/f40.dae"/>
      </geometry>
    </collision>
  </link>
  <link name="hollie_plain_right_hand_i">
    <visual>
      <geometry>
        <mesh filename="package://schunk_svh_driver/description/meshes/f41.dae"/>
      </geometry>
    </visual>
    <collision>
      <geometry>
        <mesh filename="package://schunk_svh_driver/description/meshes/f41.dae"/>
      </geometry>
    </collision>
  </link>
  <link name="hollie_plain_right_hand_m">
    <visual>
      <geometry>
        <mesh filename="package://schunk_svh_driver/description/meshes/f42.dae"/>
      </geometry>
    </visual>
    <collision>
      <geometry>
        <mesh filename="package://schunk_svh_driver/description/meshes/f42.dae"/>
      </geometry>
    </collision>
  </link>
  <link name="hollie_plain_right_hand_q">
    <visual>
      <geometry>
        <mesh filename="package://schunk_svh_driver/description/meshes/f43.dae"/>
      </geometry>
    </visual>
    <collision>
      <geometry>
        <mesh filename="package://schunk_svh_driver/description/meshes/f43.dae"/>
      </geometry>
    </collision>
  </link>
  <joint name="hollie_plain_right_hand_Thumb_Flexion" type="revolute">
    <parent link="hollie_plain_right_hand_virtual_a"/>
    <child link="hollie_plain_right_hand_a"/>
    <limit effort="1000.0" lower="0.0" upper="0.9704" velocity="1"/>
    <origin rpy="0 0 -0.9704" xyz="0 0 0"/>
    <axis xyz="0 0 1.0"/>
  </joint>
  <joint name="hollie_plain_right_hand_Thumb_Helper" type="fixed">
    <parent link="hollie_plain_right_hand_z"/>
    <child link="hollie_plain_right_hand_virtual_a"/>
    <origin rpy="0 -1.5707 3.1416" xyz="0 0 0.04596"/>
  </joint>
  <joint name="hollie_plain_right_hand_Thumb_Opposition" type="revolute">
    <parent link="hollie_plain_right_hand_e1"/>
    <child link="hollie_plain_right_hand_z"/>
    <limit effort="1000.0" lower="0.0" upper="0.9879" velocity="1"/>
    <origin rpy="0 0.2618 1.571" xyz="-0.0169 0.02626 0"/>
    <axis xyz="0 0 -1.0"/>
  </joint>
  <joint name="hollie_plain_right_hand_f1" type="fixed">
    <parent link="hollie_plain_right_hand_e1"/>
    <child link="hollie_plain_right_hand_d"/>
    <origin rpy="0 0 0" xyz="0 0 0"/>
  </joint>
  <joint name="hollie_plain_right_hand_f2" type="fixed">
    <parent link="hollie_plain_right_hand_d"/>
    <child link="hollie_plain_right_hand_h"/>
    <origin rpy="0 0 0" xyz="0 0 0"/>
  </joint>
  <joint name="hollie_plain_right_hand_f3" type="fixed">
    <parent link="hollie_plain_right_hand_h"/>
    <child link="hollie_plain_right_hand_d2"/>
    <origin rpy="0 0 0" xyz="0 0 0"/>
  </joint>
  <joint name="hollie_plain_right_hand_f4" type="fixed">
    <parent link="hollie_plain_right_hand_base_link"/>
    <child link="hollie_plain_right_hand_e1"/>
    <origin rpy="0 0 0" xyz="0 -0.01313 0"/>
  </joint>
  <joint name="hollie_plain_right_hand_j5" type="revolute">
    <parent link="hollie_plain_right_hand_e1"/>
    <child link="hollie_plain_right_hand_e2"/>
    <limit effort="1000.0" lower="0.0" upper="0.98786" velocity="1"/>
    <origin rpy="0 0 0" xyz="0.0184 0.006 0.0375"/>
    <axis xyz="0 0 1.0"/>
    <mimic joint="hollie_plain_right_hand_Thumb_Opposition" multiplier="1" offset="0"/>
  </joint>
  <joint name="hollie_plain_right_hand_f5" type="fixed">
    <parent link="hollie_plain_right_hand_e2"/>
    <child link="hollie_plain_right_hand_e3"/>
    <origin rpy="0 0 0" xyz="0 -0.0060 0"/>
  </joint>
  <joint name="hollie_plain_right_hand_f6" type="fixed">
    <parent link="hollie_plain_right_hand_e3"/>
    <child link="hollie_plain_right_hand_e"/>
    <origin rpy="0 0 0" xyz="0 0 0"/>
  </joint>
  <joint name="hollie_plain_right_hand_f7" type="fixed">
    <parent link="hollie_plain_right_hand_e"/>
    <child link="hollie_plain_right_hand_e4"/>
    <origin rpy="0 0 0" xyz="0 0 0"/>
  </joint>
  <joint name="hollie_plain_right_hand_f8" type="fixed">
    <parent link="hollie_plain_right_hand_e"/>
    <child link="hollie_plain_right_hand_e5"/>
    <origin rpy="0 0 0" xyz="0 0 0"/>
  </joint>
  <joint name="hollie_plain_right_hand_j3" type="revolute">
    <parent link="hollie_plain_right_hand_a"/>
    <child link="hollie_plain_right_hand_b"/>
    <limit effort="1000.0" lower="0.0" upper="0.98506" velocity="1"/>
    <origin rpy="0 0 0" xyz="0.0485 0 0"/>
    <axis xyz="0 0 1.0"/>
    <mimic joint="hollie_plain_right_hand_Thumb_Flexion" multiplier="1.01511" offset="0"/>
  </joint>
  <joint name="hollie_plain_right_hand_j4" type="revolute">
    <parent link="hollie_plain_right_hand_b"/>
    <child link="hollie_plain_right_hand_c"/>
    <limit effort="1000.0" lower="0.0" upper="1.406" velocity="1"/>
    <origin rpy="0 0 0" xyz="0.030 0 0"/>
    <axis xyz="0 0 1.0"/>
    <mimic joint="hollie_plain_right_hand_Thumb_Flexion" multiplier="1.44889" offset="0"/>
  </joint>
  <joint name="hollie_plain_right_hand_Index_Finger_Distal" type="revolute">
    <parent link="hollie_plain_right_hand_l"/>
    <child link="hollie_plain_right_hand_p"/>
    <limit effort="1000.0" lower="0" upper="1.334" velocity="1"/>
    <origin rpy="0 0 0" xyz="0.04804 0 0"/>
    <axis xyz="0 0 1"/>
  </joint>
  <joint name="hollie_plain_right_hand_Index_Finger_Proximal" type="revolute">
    <parent link="hollie_plain_right_hand_virtual_l"/>
    <child link="hollie_plain_right_hand_l"/>
    <limit effort="1000.0" lower="0.0" upper="0.79849" velocity="1"/>
    <origin rpy="-1.5707 0 0" xyz="0 0 0"/>
    <axis xyz="0 0 1"/>
  </joint>
  <joint name="hollie_plain_right_hand_j14" type="revolute">
    <parent link="hollie_plain_right_hand_p"/>
    <child link="hollie_plain_right_hand_t"/>
    <limit effort="1000.0" lower="0" upper="1.394" velocity="1"/>
    <origin rpy="0 0 0" xyz="0.026 0 0"/>
    <axis xyz="0 0 1"/>
    <mimic joint="hollie_plain_right_hand_Index_Finger_Distal" multiplier="1.0450" offset="0"/>
  </joint>
  <joint name="hollie_plain_right_hand_Middle_Finger_Proximal" type="revolute">
    <parent link="hollie_plain_right_hand_virtual_k"/>
    <child link="hollie_plain_right_hand_k"/>
    <limit effort="1000.0" lower="0.0" upper="0.79849" velocity="1"/>
    <origin rpy="-1.5707 0 0" xyz="0 0 0"/>
    <axis xyz="0 0 1"/>
  </joint>
  <joint name="hollie_plain_right_hand_Middle_Finger_Distal" type="revolute">
    <parent link="hollie_plain_right_hand_k"/>
    <child link="hollie_plain_right_hand_o"/>
    <limit effort="1000.0" lower="0" upper="1.334" velocity="1"/>
    <origin rpy="0 0 0" xyz="0.05004 0 0"/>
    <axis xyz="0 0 1"/>
  </joint>
  <joint name="hollie_plain_right_hand_j15" type="revolute">
    <parent link="hollie_plain_right_hand_o"/>
    <child link="hollie_plain_right_hand_s"/>
    <limit effort="1000.0" lower="0" upper="1.334" velocity="1"/>
    <origin rpy="0 0 0" xyz="0.032 0 0"/>
    <axis xyz="0 0 1"/>
    <mimic joint="hollie_plain_right_hand_Middle_Finger_Distal" multiplier="1.0454" offset="0"/>
  </joint>
  <joint name="hollie_plain_right_hand_Ring_Finger" type="revolute">
    <parent link="hollie_plain_right_hand_virtual_j"/>
    <child link="hollie_plain_right_hand_j"/>
    <limit effort="1000.0" lower="0.0" upper="0.98175" velocity="1"/>
    <origin rpy="1.5707 0 0" xyz="0 0 0"/>
    <axis xyz="0 0 1"/>
  </joint>
  <joint name="hollie_plain_right_hand_j12" type="revolute">
    <parent link="hollie_plain_right_hand_j"/>
    <child link="hollie_plain_right_hand_n"/>
    <limit effort="1000.0" lower="0" upper="1.334" velocity="1"/>
    <origin rpy="0 0 0" xyz="0.05004 0 0"/>
    <axis xyz="0 0 1"/>
    <mimic joint="hollie_plain_right_hand_Ring_Finger" multiplier="1.3588" offset="0"/>
  </joint>
  <joint name="hollie_plain_right_hand_j16" type="revolute">
    <parent link="hollie_plain_right_hand_n"/>
    <child link="hollie_plain_right_hand_r"/>
    <limit effort="1000.0" lower="0" upper="1.395" velocity="1"/>
    <origin rpy="0 0 0" xyz="0.032 0 0"/>
    <axis xyz="0 0 1"/>
    <mimic joint="hollie_plain_right_hand_Ring_Finger" multiplier="1.42093" offset="0"/>
  </joint>
  <joint name="hollie_plain_right_hand_Pinky" type="revolute">
    <parent link="hollie_plain_right_hand_virtual_i"/>
    <child link="hollie_plain_right_hand_i"/>
    <limit effort="1000.0" lower="0.0" upper="0.98175" velocity="1"/>
    <origin rpy="1.5707 0 0" xyz="0 0 0"/>
    <axis xyz="0 0 1"/>
  </joint>
  <joint name="hollie_plain_right_hand_j13" type="revolute">
    <parent link="hollie_plain_right_hand_i"/>
    <child link="hollie_plain_right_hand_m"/>
    <limit effort="1000.0" lower="0" upper="1.334" velocity="1"/>
    <origin rpy="0 0 0" xyz="0.04454 0 0"/>
    <axis xyz="0 0 1"/>
    <mimic joint="hollie_plain_right_hand_Pinky" multiplier="1.35880" offset="0"/>
  </joint>
  <joint name="hollie_plain_right_hand_j17" type="revolute">
    <parent link="hollie_plain_right_hand_m"/>
    <child link="hollie_plain_right_hand_q"/>
    <limit effort="1000.0" lower="0" upper="1.3971" velocity="1"/>
    <origin rpy="0 0 0" xyz="0.022 0 0"/>
    <axis xyz="0 0 1"/>
    <mimic joint="hollie_plain_right_hand_Pinky" multiplier="1.42307" offset="0"/>
  </joint>
  <joint name="hollie_plain_right_hand_index_spread" type="revolute">
    <parent link="hollie_plain_right_hand_d2"/>
    <child link="hollie_plain_right_hand_virtual_l"/>
    <limit effort="1000.0" lower="0.0" upper="0.28833" velocity="1"/>
    <origin rpy="0 -1.5707 1.5707" xyz="-0.025 0 0.110"/>
    <axis xyz="0 0 1.0"/>
    <mimic joint="hollie_plain_right_hand_Finger_Spread" multiplier="0.5" offset="0"/>
  </joint>
  <joint name="hollie_plain_right_hand_middle_spread_dummy" type="fixed">
    <parent link="hollie_plain_right_hand_d"/>
    <child link="hollie_plain_right_hand_virtual_k"/>
    <origin rpy="0 -1.5707 1.5707" xyz="0 0 0.110"/>
  </joint>
  <joint name="hollie_plain_right_hand_ring_spread" type="revolute">
    <parent link="hollie_plain_right_hand_e5"/>
    <child link="hollie_plain_right_hand_virtual_j"/>
    <limit effort="1000.0" lower="0.0" upper="0.28833" velocity="1"/>
    <origin rpy="-1.5707 -1.5707 0" xyz="0.003855 0 0.0655"/>
    <axis xyz="0 0 1.0"/>
    <mimic joint="hollie_plain_right_hand_Finger_Spread" multiplier="0.5" offset="0"/>
  </joint>
  <joint name="hollie_plain_right_hand_Finger_Spread" type="revolute">
    <parent link="hollie_plain_right_hand_e4"/>
    <child link="hollie_plain_right_hand_virtual_i"/>
    <limit effort="1000.0" lower="0.0" upper="0.5829" velocity="1"/>
    <origin rpy="-1.5707 -1.5707 0" xyz="0.025355 0 0.056"/>
    <axis xyz="0 0 1.0"/>
  </joint>
  <joint name="hollie_plain_left_arm_0_joint" type="fixed">
    <origin rpy="-1.57075 0 0" xyz="0 0.1425 0"/>
    <parent link="hollie_plain_left_arm_calibration"/>
    <child link="hollie_plain_left_arm_0_link"/>
  </joint>
  <link name="hollie_plain_left_arm_0_link">
    <inertial>
      <origin rpy="0 0 0" xyz="0 0 0"/>
      <mass value="0.29364"/>
      <inertia ixx="0.01" ixy="0" ixz="0" iyy="0.01" iyz="0" izz="0.01"/>
    </inertial>
    <visual>
      <origin rpy="0 0 0" xyz="0 0 0"/>
      <geometry>
        <mesh filename="package://schunk_description/meshes/lwa4p/arm_0_link.dae"/>
      </geometry>
      <!-- <material name="Schunk/LightGrey" /> -->
    </visual>
    <collision>
      <origin rpy="0 0 0" xyz="0 0 0"/>
      <geometry>
        <mesh filename="package://schunk_description/meshes/lwa4p/arm_0_link.stl"/>
      </geometry>
    </collision>
  </link>
  <joint name="hollie_plain_left_arm_1_joint" type="revolute">
    <origin rpy="0 0 0" xyz="0 0 0.11"/>
    <parent link="hollie_plain_left_arm_0_link"/>
    <child link="hollie_plain_left_arm_1_link"/>
    <axis xyz="0 0 1"/>
    <calibration rising="2.1"/>
    <dynamics damping="10"/>
    <limit effort="370" lower="-6.2831853" upper="6.2831853" velocity="2.0"/>
    <safety_controller k_position="20" k_velocity="50" soft_lower_limit="-6.2731853" soft_upper_limit="6.2731853"/>
  </joint>
  <link name="hollie_plain_left_arm_1_link">
    <inertial>
      <origin rpy="0 0 0" xyz="0 0 0"/>
      <mass value="0.29364"/>
      <inertia ixx="0.01" ixy="0" ixz="0" iyy="0.01" iyz="0" izz="0.01"/>
    </inertial>
    <visual>
      <origin rpy="0 0 0" xyz="0 0 0"/>
      <geometry>
        <mesh filename="package://schunk_description/meshes/lwa4p/arm_1_link.dae"/>
      </geometry>
      <!-- <material name="Schunk/Blue" /> -->
    </visual>
    <collision>
      <origin rpy="0 0 0" xyz="0 0 0"/>
      <geometry>
        <mesh filename="package://schunk_description/meshes/lwa4p/arm_1_link.stl"/>
      </geometry>
    </collision>
  </link>
  <joint name="hollie_plain_left_arm_2_joint" type="revolute">
    <origin rpy="1.5708 0 0" xyz="0 0 0"/>
    <parent link="hollie_plain_left_arm_1_link"/>
    <child link="hollie_plain_left_arm_2_link"/>
    <axis xyz="0 0 1"/>
    <calibration rising="2.1"/>
    <dynamics damping="10"/>
    <limit effort="370" lower="-2.0943951" upper="2.0943951" velocity="2.0"/>
    <safety_controller k_position="20" k_velocity="50" soft_lower_limit="-2.0843" soft_upper_limit="2.0843"/>
  </joint>
  <link name="hollie_plain_left_arm_2_link">
    <inertial>
      <origin rpy="0 0 0" xyz="0 0 0"/>
      <mass value="1.68311"/>
      <inertia ixx="0.03" ixy="0" ixz="0" iyy="0.03" iyz="0" izz="0.03"/>
    </inertial>
    <visual>
      <origin rpy="0 0 0" xyz="0 0 0"/>
      <geometry>
        <mesh filename="package://schunk_description/meshes/lwa4p/arm_2_link.dae"/>
      </geometry>
      <!-- <material name="Schunk/LightGrey" /> -->
    </visual>
    <collision>
      <origin rpy="0 0 0" xyz="0 0 0"/>
      <geometry>
        <mesh filename="package://schunk_description/meshes/lwa4p/arm_2_link.stl"/>
      </geometry>
    </collision>
  </link>
  <joint name="hollie_plain_left_arm_3_joint" type="revolute">
    <origin rpy="0 3.14159 0" xyz="0 0.350 0"/>
    <parent link="hollie_plain_left_arm_2_link"/>
    <child link="hollie_plain_left_arm_3_link"/>
    <axis xyz="0 0 1"/>
    <calibration rising="2.1"/>
    <dynamics damping="5"/>
    <limit effort="176" lower="-6.2831853" upper="6.2831853" velocity="2.0"/>
    <safety_controller k_position="20" k_velocity="25" soft_lower_limit="-6.2731853" soft_upper_limit="6.2731853"/>
  </joint>
  <link name="hollie_plain_left_arm_3_link">
    <inertial>
      <origin rpy="0 0 0" xyz="0 0 0"/>
      <mass value="2.1"/>
      <inertia ixx="0.03" ixy="0" ixz="0" iyy="0.03" iyz="0" izz="0.03"/>
    </inertial>
    <visual>
      <origin rpy="0 0 0" xyz="0 0 0"/>
      <geometry>
        <mesh filename="package://schunk_description/meshes/lwa4p/arm_3_link.dae"/>
      </geometry>
      <!-- <material name="Schunk/Blue" /> -->
    </visual>
    <collision>
      <origin rpy="0 0 0" xyz="0 0 0"/>
      <geometry>
        <mesh filename="package://schunk_description/meshes/lwa4p/arm_3_link.stl"/>
      </geometry>
    </collision>
  </link>
  <joint name="hollie_plain_left_arm_4_joint" type="revolute">
    <origin rpy="-1.5708 3.14159 0" xyz="0 0 0"/>
    <parent link="hollie_plain_left_arm_3_link"/>
    <child link="hollie_plain_left_arm_4_link"/>
    <axis xyz="0 0 1"/>
    <calibration rising="2.1"/>
    <dynamics damping="5"/>
    <limit effort="176" lower="-2.0943951" upper="2.0943951" velocity="2.0"/>
    <safety_controller k_position="20" k_velocity="25" soft_lower_limit="-2.0843951" soft_upper_limit="2.0843951"/>
  </joint>
  <link name="hollie_plain_left_arm_4_link">
    <inertial>
      <origin rpy="0 0 0" xyz="0 0 0"/>
      <mass value="1.68311"/>
      <inertia ixx="0.03" ixy="0" ixz="0" iyy="0.03" iyz="0" izz="0.03"/>
    </inertial>
    <visual>
      <origin rpy="0 0 0" xyz="0 0 0"/>
      <geometry>
        <mesh filename="package://schunk_description/meshes/lwa4p/arm_4_link.dae"/>
      </geometry>
      <!-- <material name="Schunk/LightGrey" /> -->
    </visual>
    <collision>
      <origin rpy="0 0 0" xyz="0 0 0"/>
      <geometry>
        <mesh filename="package://schunk_description/meshes/lwa4p/arm_4_link.stl"/>
      </geometry>
    </collision>
  </link>
  <joint name="hollie_plain_left_arm_5_joint" type="revolute">
    <origin rpy="1.5708 0 3.14159" xyz="0 0.005263 0.365"/>
    <parent link="hollie_plain_left_arm_4_link"/>
    <child link="hollie_plain_left_arm_5_link"/>
    <axis xyz="0 0 1"/>
    <calibration rising="2.1"/>
    <dynamics damping="5"/>
    <limit effort="41.6" lower="-6.2831853" upper="6.2831853" velocity="2.0"/>
    <safety_controller k_position="20" k_velocity="25" soft_lower_limit="-6.2731853" soft_upper_limit="6.2731853"/>
  </joint>
  <link name="hollie_plain_left_arm_5_link">
    <inertial>
      <origin rpy="0 0 0" xyz="0 0 0"/>
      <mass value="0.807"/>
      <inertia ixx="0.03" ixy="0" ixz="0" iyy="0.03" iyz="0" izz="0.03"/>
    </inertial>
    <visual>
      <origin rpy="0 0 0" xyz="0 0 0"/>
      <geometry>
        <mesh filename="package://schunk_description/meshes/lwa4p/arm_5_link.dae"/>
      </geometry>
      <!-- <material name="Schunk/Blue" /> -->
    </visual>
    <collision>
      <origin rpy="0 0 0" xyz="0 0 0"/>
      <geometry>
        <mesh filename="package://schunk_description/meshes/lwa4p/arm_5_link.stl"/>
      </geometry>
    </collision>
  </link>
  <joint name="hollie_plain_left_arm_6_joint" type="revolute">
    <origin rpy="-1.5708 0 0" xyz="0 0 0"/>
    <parent link="hollie_plain_left_arm_5_link"/>
    <child link="hollie_plain_left_arm_6_link"/>
    <axis xyz="0 0 1"/>
    <calibration rising="2.1"/>
    <dynamics damping="5"/>
    <limit effort="20.1" lower="-2.0943951" upper="2.0943951" velocity="2.0"/>
    <safety_controller k_position="20" k_velocity="25" soft_lower_limit="-2.0843951" soft_upper_limit="2.0843951"/>
  </joint>
  <link name="hollie_plain_left_arm_6_link">
    <inertial>
      <origin rpy="0 0 0" xyz="0 0 0"/>
      <mass value="0.819"/>
      <inertia ixx="0.01" ixy="0" ixz="0" iyy="0.01" iyz="0" izz="0.01"/>
    </inertial>
    <visual>
      <origin rpy="0 0 0" xyz="0 0 0"/>
      <geometry>
        <mesh filename="package://schunk_description/meshes/lwa4p/arm_6_link.dae"/>
      </geometry>
      <!-- <material name="Schunk/LightGrey" /> -->
    </visual>
    <collision>
      <origin rpy="0 0 0" xyz="0 0 0"/>
      <geometry>
        <mesh filename="package://schunk_description/meshes/lwa4p/arm_6_link.stl"/>
      </geometry>
    </collision>
  </link>
  <gazebo reference="hollie_plain_left_arm_0_link">
    <material value="Schunk/LightGrey"/>
    <turnGravityOff>false</turnGravityOff>
    <selfCollide>true</selfCollide>
  </gazebo>
  <gazebo reference="hollie_plain_left_arm_1_link">
    <material value="Schunk/Blue"/>
    <turnGravityOff>false</turnGravityOff>
    <selfCollide>true</selfCollide>
  </gazebo>
  <gazebo reference="hollie_plain_left_arm_2_link">
    <material value="Schunk/LightGrey"/>
    <turnGravityOff>false</turnGravityOff>
    <selfCollide>true</selfCollide>
  </gazebo>
  <gazebo reference="hollie_plain_left_arm_3_link">
    <material value="Schunk/Blue"/>
    <turnGravityOff>false</turnGravityOff>
    <selfCollide>true</selfCollide>
  </gazebo>
  <gazebo reference="hollie_plain_left_arm_4_link">
    <material value="Schunk/LightGrey"/>
    <turnGravityOff>false</turnGravityOff>
    <selfCollide>true</selfCollide>
  </gazebo>
  <gazebo reference="hollie_plain_left_arm_5_link">
    <material value="Schunk/Blue"/>
    <turnGravityOff>false</turnGravityOff>
    <selfCollide>true</selfCollide>
  </gazebo>
  <gazebo reference="hollie_plain_left_arm_6_link">
    <material value="Schunk/LightGrey"/>
    <turnGravityOff>false</turnGravityOff>
    <selfCollide>true</selfCollide>
  </gazebo>
  <transmission name="hollie_plain_left_arm_1_trans">
    <type>transmission_interface/SimpleTransmission</type>
    <joint name="hollie_plain_left_arm_1_joint"/>
    <actuator name="hollie_plain_left_arm_1_motor">
      <hardwareInterface>EffortJointInterface</hardwareInterface>
      <mechanicalReduction>1</mechanicalReduction>
    </actuator>
  </transmission>
  <transmission name="hollie_plain_left_arm_2_trans">
    <type>transmission_interface/SimpleTransmission</type>
    <joint name="hollie_plain_left_arm_2_joint"/>
    <actuator name="hollie_plain_left_arm_2_motor">
      <hardwareInterface>EffortJointInterface</hardwareInterface>
      <mechanicalReduction>1</mechanicalReduction>
    </actuator>
  </transmission>
  <transmission name="hollie_plain_left_arm_3_trans">
    <type>transmission_interface/SimpleTransmission</type>
    <joint name="hollie_plain_left_arm_3_joint"/>
    <actuator name="hollie_plain_left_arm_3_motor">
      <hardwareInterface>EffortJointInterface</hardwareInterface>
      <mechanicalReduction>1</mechanicalReduction>
    </actuator>
  </transmission>
  <transmission name="hollie_plain_left_arm_4_trans">
    <type>transmission_interface/SimpleTransmission</type>
    <joint name="hollie_plain_left_arm_4_joint"/>
    <actuator name="hollie_plain_left_arm_4_motor">
      <hardwareInterface>EffortJointInterface</hardwareInterface>
      <mechanicalReduction>1</mechanicalReduction>
    </actuator>
  </transmission>
  <transmission name="hollie_plain_left_arm_5_trans">
    <type>transmission_interface/SimpleTransmission</type>
    <joint name="hollie_plain_left_arm_5_joint"/>
    <actuator name="hollie_plain_left_arm_5_motor">
      <hardwareInterface>EffortJointInterface</hardwareInterface>
      <mechanicalReduction>1</mechanicalReduction>
    </actuator>
  </transmission>
  <transmission name="hollie_plain_left_arm_6_trans">
    <type>transmission_interface/SimpleTransmission</type>
    <joint name="hollie_plain_left_arm_6_joint"/>
    <actuator name="hollie_plain_left_arm_6_motor">
      <hardwareInterface>EffortJointInterface</hardwareInterface>
      <mechanicalReduction>1</mechanicalReduction>
    </actuator>
  </transmission>
  <joint name="hollie_plain_left_hand_base_joint" type="fixed">
    <origin rpy="0 0 0" xyz="0 0 0.1"/>
    <parent link="hollie_plain_left_arm_6_link"/>
    <child link="hollie_plain_left_hand_base_link"/>
  </joint>
  <link name="hollie_plain_left_hand_base_link">
    <origin rpy="0 0 0" xyz="0 0 0.1"/>
    <visual>
      <origin rpy="0 0 0" xyz="0 0 -0.032"/>
      <geometry>
        <mesh filename="package://schunk_svh_driver/description/meshes/base10.dae"/>
      </geometry>
    </visual>
    <collision>
      <origin rpy="0 0 0" xyz="0 0 -0.032"/>
      <geometry>
        <mesh filename="package://schunk_svh_driver/description/meshes/base10.dae"/>
      </geometry>
    </collision>
  </link>
  <link name="hollie_plain_left_hand_d">
    <!-- <visual> -->
    <!-- 	<geometry> -->
    <!-- 	  <cylinder length="0.110" radius="${cyl_radius}" /> -->
    <!-- 	</geometry> -->
    <!-- 	<material name="${name}_green" /> -->
    <!-- </visual> -->
  </link>
  <link name="hollie_plain_left_hand_h">
    <!-- <visual> -->
    <!-- 	<origin rpy="0 1.571 0" xyz="${side*(-0.0125)} 0 0.0825" /> -->
    <!-- 	<geometry> -->
    <!-- 	  <cylinder length="0.025" radius="${cyl_radius}" /> -->
    <!-- 	</geometry> -->
    <!-- 	<material name="${name}_green" /> -->
    <!-- </visual> -->
  </link>
  <link name="hollie_plain_left_hand_d2">
    <!-- <visual> -->
    <!-- 	<origin rpy="0 0 0" xyz="${side*(-0.025)} 0 0.09625" /> -->
    <!-- 	<geometry> -->
    <!-- 	  <cylinder length="0.0275" radius="${cyl_radius}" /> -->
    <!-- 	</geometry> -->
    <!-- 	<material name="${name}_green" /> -->
    <!-- </visual> -->
  </link>
  <link name="hollie_plain_left_hand_e1">
    <visual>
      <origin rpy="0 0 0" xyz="0 0.01313 0"/>
      <geometry>
        <mesh filename="package://schunk_svh_driver/description/meshes/h10.dae" scale="-1.0 1 1"/>
      </geometry>
    </visual>
    <collision>
      <origin rpy="0 0 0" xyz="0 0.01313 0"/>
      <geometry>
        <mesh filename="package://schunk_svh_driver/description/meshes/h10.dae" scale="-1.0 1 1"/>
      </geometry>
    </collision>
  </link>
  <link name="hollie_plain_left_hand_e2">
    <visual>
      <origin xyz="0.0007 0 -0.01002"/>
      <geometry>
        <mesh filename="package://schunk_svh_driver/description/meshes/h11.dae" scale="-1.0 1 1"/>
      </geometry>
    </visual>
    <collision>
      <origin xyz="0.0007 0 -0.01002"/>
      <geometry>
        <mesh filename="package://schunk_svh_driver/description/meshes/h11.dae" scale="-1.0 1 1"/>
      </geometry>
    </collision>
  </link>
  <link name="hollie_plain_left_hand_e3">
    <!-- <visual> -->
    <!-- 	<origin rpy="0 0 0" xyz="${side*(0.0175)} 0 0.015" /> -->
    <!-- 	<geometry> -->
    <!-- 	  <cylinder length="0.03" radius="${cyl_radius}" /> -->
    <!-- 	</geometry> -->
    <!-- 	<material name="green" /> -->
    <!-- </visual> -->
  </link>
  <link name="hollie_plain_left_hand_e">
    </link>
  <link name="hollie_plain_left_hand_e4">
    <!-- <visual> -->
    <!-- 	<origin rpy="0 0 0" xyz="${side*(0.02825)} 0 0.043" /> -->
    <!-- 	<geometry> -->
    <!-- 	  <cylinder length="0.026" radius="${cyl_radius}" /> -->
    <!-- 	</geometry> -->
    <!-- 	<material name="green" /> -->
    <!-- </visual> -->
  </link>
  <link name="hollie_plain_left_hand_e5">
    <!-- <visual> -->
    <!-- 	<origin rpy="0 0 0" xyz="${side*(0.00675)} 0 0.04775" /> -->
    <!-- 	<geometry> -->
    <!-- 	  <cylinder length="0.0355" radius="${cyl_radius}" /> -->
    <!-- 	</geometry> -->
    <!-- 	<material name="green" /> -->
    <!-- </visual> -->
  </link>
  <link name="hollie_plain_left_hand_z">
    <visual>
      <origin xyz="0 0 0.02442"/>
      <geometry>
        <mesh filename="package://schunk_svh_driver/description/meshes/d10.dae" scale="1 -1.0 1"/>
      </geometry>
    </visual>
    <collision>
      <origin xyz="0 0 0.02442"/>
      <geometry>
        <mesh filename="package://schunk_svh_driver/description/meshes/d10.dae" scale="1 -1.0 1"/>
      </geometry>
    </collision>
  </link>
  <link name="hollie_plain_left_hand_virtual_a"/>
  <link name="hollie_plain_left_hand_a">
    <visual>
      <geometry>
        <mesh filename="package://schunk_svh_driver/description/meshes/d11.dae" scale="1 -1.0 -1.0"/>
      </geometry>
    </visual>
    <collision>
      <geometry>
        <mesh filename="package://schunk_svh_driver/description/meshes/d11.dae" scale="1 -1.0 -1.0"/>
      </geometry>
    </collision>
  </link>
  <link name="hollie_plain_left_hand_b">
    <visual>
      <geometry>
        <mesh filename="package://schunk_svh_driver/description/meshes/d12.dae" scale="1 -1.0 -1.0"/>
      </geometry>
    </visual>
    <collision>
      <geometry>
        <mesh filename="package://schunk_svh_driver/description/meshes/d12.dae" scale="1 -1.0 -1.0"/>
      </geometry>
    </collision>
  </link>
  <link name="hollie_plain_left_hand_c">
    <visual>
      <geometry>
        <mesh filename="package://schunk_svh_driver/description/meshes/d13.dae" scale="1 -1.0 -1.0"/>
      </geometry>
    </visual>
    <collision>
      <geometry>
        <mesh filename="package://schunk_svh_driver/description/meshes/d13.dae" scale="1 -1.0 -1.0"/>
      </geometry>
    </collision>
  </link>
  <link name="hollie_plain_left_hand_virtual_l">
    <visual>
      <origin xyz="0 0 0.01321"/>
      <geometry>
        <mesh filename="package://schunk_svh_driver/description/meshes/f10.dae"/>
      </geometry>
    </visual>
    <collision>
      <origin xyz="0 0 0.01321"/>
      <geometry>
        <mesh filename="package://schunk_svh_driver/description/meshes/f10.dae"/>
      </geometry>
    </collision>
  </link>
  <link name="hollie_plain_left_hand_l">
    <visual>
      <geometry>
        <mesh filename="package://schunk_svh_driver/description/meshes/f11.dae"/>
      </geometry>
    </visual>
    <collision>
      <geometry>
        <mesh filename="package://schunk_svh_driver/description/meshes/f11.dae"/>
      </geometry>
    </collision>
  </link>
  <link name="hollie_plain_left_hand_p">
    <visual>
      <geometry>
        <mesh filename="package://schunk_svh_driver/description/meshes/f12.dae"/>
      </geometry>
    </visual>
    <collision>
      <geometry>
        <mesh filename="package://schunk_svh_driver/description/meshes/f12.dae"/>
      </geometry>
    </collision>
  </link>
  <link name="hollie_plain_left_hand_t">
    <visual>
      <geometry>
        <mesh filename="package://schunk_svh_driver/description/meshes/f13.dae"/>
      </geometry>
    </visual>
    <collision>
      <geometry>
        <mesh filename="package://schunk_svh_driver/description/meshes/f13.dae"/>
      </geometry>
    </collision>
  </link>
  <link name="hollie_plain_left_hand_virtual_k">
    <visual>
      <origin xyz="0 0 0.01321"/>
      <geometry>
        <mesh filename="package://schunk_svh_driver/description/meshes/f20.dae"/>
      </geometry>
    </visual>
    <collision>
      <origin xyz="0 0 0.01321"/>
      <geometry>
        <mesh filename="package://schunk_svh_driver/description/meshes/f20.dae"/>
      </geometry>
    </collision>
  </link>
  <link name="hollie_plain_left_hand_k">
    <visual>
      <geometry>
        <mesh filename="package://schunk_svh_driver/description/meshes/f21.dae"/>
      </geometry>
    </visual>
    <collision>
      <geometry>
        <mesh filename="package://schunk_svh_driver/description/meshes/f21.dae"/>
      </geometry>
    </collision>
  </link>
  <link name="hollie_plain_left_hand_o">
    <visual>
      <geometry>
        <mesh filename="package://schunk_svh_driver/description/meshes/f22.dae"/>
      </geometry>
    </visual>
    <collision>
      <geometry>
        <mesh filename="package://schunk_svh_driver/description/meshes/f22.dae"/>
      </geometry>
    </collision>
  </link>
  <link name="hollie_plain_left_hand_s">
    <visual>
      <geometry>
        <mesh filename="package://schunk_svh_driver/description/meshes/f23.dae"/>
      </geometry>
    </visual>
    <collision>
      <geometry>
        <mesh filename="package://schunk_svh_driver/description/meshes/f23.dae"/>
      </geometry>
    </collision>
  </link>
  <link name="hollie_plain_left_hand_virtual_j">
    <visual>
      <origin xyz="0 0 -0.01321"/>
      <geometry>
        <mesh filename="package://schunk_svh_driver/description/meshes/f30.dae"/>
      </geometry>
    </visual>
    <collision>
      <origin xyz="0 0 -0.01321"/>
      <geometry>
        <mesh filename="package://schunk_svh_driver/description/meshes/f30.dae"/>
      </geometry>
    </collision>
  </link>
  <link name="hollie_plain_left_hand_j">
    <visual>
      <geometry>
        <mesh filename="package://schunk_svh_driver/description/meshes/f31.dae"/>
      </geometry>
    </visual>
    <collision>
      <geometry>
        <mesh filename="package://schunk_svh_driver/description/meshes/f31.dae"/>
      </geometry>
    </collision>
  </link>
  <link name="hollie_plain_left_hand_n">
    <visual>
      <geometry>
        <mesh filename="package://schunk_svh_driver/description/meshes/f32.dae"/>
      </geometry>
    </visual>
    <collision>
      <geometry>
        <mesh filename="package://schunk_svh_driver/description/meshes/f32.dae"/>
      </geometry>
    </collision>
  </link>
  <link name="hollie_plain_left_hand_r">
    <visual>
      <geometry>
        <mesh filename="package://schunk_svh_driver/description/meshes/f33.dae"/>
      </geometry>
    </visual>
    <collision>
      <geometry>
        <mesh filename="package://schunk_svh_driver/description/meshes/f33.dae"/>
      </geometry>
    </collision>
  </link>
  <link name="hollie_plain_left_hand_virtual_i">
    <visual>
      <origin xyz="0 0 -0.01321"/>
      <geometry>
        <mesh filename="package://schunk_svh_driver/description/meshes/f40.dae"/>
      </geometry>
    </visual>
    <collision>
      <origin xyz="0 0 -0.01321"/>
      <geometry>
        <mesh filename="package://schunk_svh_driver/description/meshes/f40.dae"/>
      </geometry>
    </collision>
  </link>
  <link name="hollie_plain_left_hand_i">
    <visual>
      <geometry>
        <mesh filename="package://schunk_svh_driver/description/meshes/f41.dae"/>
      </geometry>
    </visual>
    <collision>
      <geometry>
        <mesh filename="package://schunk_svh_driver/description/meshes/f41.dae"/>
      </geometry>
    </collision>
  </link>
  <link name="hollie_plain_left_hand_m">
    <visual>
      <geometry>
        <mesh filename="package://schunk_svh_driver/description/meshes/f42.dae"/>
      </geometry>
    </visual>
    <collision>
      <geometry>
        <mesh filename="package://schunk_svh_driver/description/meshes/f42.dae"/>
      </geometry>
    </collision>
  </link>
  <link name="hollie_plain_left_hand_q">
    <visual>
      <geometry>
        <mesh filename="package://schunk_svh_driver/description/meshes/f43.dae"/>
      </geometry>
    </visual>
    <collision>
      <geometry>
        <mesh filename="package://schunk_svh_driver/description/meshes/f43.dae"/>
      </geometry>
    </collision>
  </link>
  <joint name="hollie_plain_left_hand_Thumb_Flexion" type="revolute">
    <parent link="hollie_plain_left_hand_virtual_a"/>
    <child link="hollie_plain_left_hand_a"/>
    <limit effort="1000.0" lower="0.0" upper="0.9704" velocity="1"/>
    <origin rpy="0 0 0.9704" xyz="0 0 0"/>
    <axis xyz="0 0 -1.0"/>
  </joint>
  <joint name="hollie_plain_left_hand_Thumb_Helper" type="fixed">
    <parent link="hollie_plain_left_hand_z"/>
    <child link="hollie_plain_left_hand_virtual_a"/>
    <origin rpy="0 -1.5707 3.1416" xyz="0 0 0.04596"/>
  </joint>
  <joint name="hollie_plain_left_hand_Thumb_Opposition" type="revolute">
    <parent link="hollie_plain_left_hand_e1"/>
    <child link="hollie_plain_left_hand_z"/>
    <limit effort="1000.0" lower="0.0" upper="0.9879" velocity="1"/>
    <origin rpy="0 0.2618 1.571" xyz="0.0169 0.02626 0"/>
    <axis xyz="0 0 1.0"/>
  </joint>
  <joint name="hollie_plain_left_hand_f1" type="fixed">
    <parent link="hollie_plain_left_hand_e1"/>
    <child link="hollie_plain_left_hand_d"/>
    <origin rpy="0 0 0" xyz="0 0 0"/>
  </joint>
  <joint name="hollie_plain_left_hand_f2" type="fixed">
    <parent link="hollie_plain_left_hand_d"/>
    <child link="hollie_plain_left_hand_h"/>
    <origin rpy="0 0 0" xyz="0 0 0"/>
  </joint>
  <joint name="hollie_plain_left_hand_f3" type="fixed">
    <parent link="hollie_plain_left_hand_h"/>
    <child link="hollie_plain_left_hand_d2"/>
    <origin rpy="0 0 0" xyz="0 0 0"/>
  </joint>
  <joint name="hollie_plain_left_hand_f4" type="fixed">
    <parent link="hollie_plain_left_hand_base_link"/>
    <child link="hollie_plain_left_hand_e1"/>
    <origin rpy="0 0 0" xyz="0 -0.01313 0"/>
  </joint>
  <joint name="hollie_plain_left_hand_j5" type="revolute">
    <parent link="hollie_plain_left_hand_e1"/>
    <child link="hollie_plain_left_hand_e2"/>
    <limit effort="1000.0" lower="0.0" upper="0.98786" velocity="1"/>
    <origin rpy="0 0 0" xyz="-0.0184 0.006 0.0375"/>
    <axis xyz="0 0 -1.0"/>
    <mimic joint="hollie_plain_left_hand_Thumb_Opposition" multiplier="1" offset="0"/>
  </joint>
  <joint name="hollie_plain_left_hand_f5" type="fixed">
    <parent link="hollie_plain_left_hand_e2"/>
    <child link="hollie_plain_left_hand_e3"/>
    <origin rpy="0 0 0" xyz="0 -0.0060 0"/>
  </joint>
  <joint name="hollie_plain_left_hand_f6" type="fixed">
    <parent link="hollie_plain_left_hand_e3"/>
    <child link="hollie_plain_left_hand_e"/>
    <origin rpy="0 0 0" xyz="0 0 0"/>
  </joint>
  <joint name="hollie_plain_left_hand_f7" type="fixed">
    <parent link="hollie_plain_left_hand_e"/>
    <child link="hollie_plain_left_hand_e4"/>
    <origin rpy="0 0 0" xyz="0 0 0"/>
  </joint>
  <joint name="hollie_plain_left_hand_f8" type="fixed">
    <parent link="hollie_plain_left_hand_e"/>
    <child link="hollie_plain_left_hand_e5"/>
    <origin rpy="0 0 0" xyz="0 0 0"/>
  </joint>
  <joint name="hollie_plain_left_hand_j3" type="revolute">
    <parent link="hollie_plain_left_hand_a"/>
    <child link="hollie_plain_left_hand_b"/>
    <limit effort="1000.0" lower="0.0" upper="0.98506" velocity="1"/>
    <origin rpy="0 0 0" xyz="0.0485 0 0"/>
    <axis xyz="0 0 -1.0"/>
    <mimic joint="hollie_plain_left_hand_Thumb_Flexion" multiplier="1.01511" offset="0"/>
  </joint>
  <joint name="hollie_plain_left_hand_j4" type="revolute">
    <parent link="hollie_plain_left_hand_b"/>
    <child link="hollie_plain_left_hand_c"/>
    <limit effort="1000.0" lower="0.0" upper="1.406" velocity="1"/>
    <origin rpy="0 0 0" xyz="0.030 0 0"/>
    <axis xyz="0 0 -1.0"/>
    <mimic joint="hollie_plain_left_hand_Thumb_Flexion" multiplier="1.44889" offset="0"/>
  </joint>
  <joint name="hollie_plain_left_hand_Index_Finger_Distal" type="revolute">
    <parent link="hollie_plain_left_hand_l"/>
    <child link="hollie_plain_left_hand_p"/>
    <limit effort="1000.0" lower="0" upper="1.334" velocity="1"/>
    <origin rpy="0 0 0" xyz="0.04804 0 0"/>
    <axis xyz="0 0 1"/>
  </joint>
  <joint name="hollie_plain_left_hand_Index_Finger_Proximal" type="revolute">
    <parent link="hollie_plain_left_hand_virtual_l"/>
    <child link="hollie_plain_left_hand_l"/>
    <limit effort="1000.0" lower="0.0" upper="0.79849" velocity="1"/>
    <origin rpy="-1.5707 0 0" xyz="0 0 0"/>
    <axis xyz="0 0 1"/>
  </joint>
  <joint name="hollie_plain_left_hand_j14" type="revolute">
    <parent link="hollie_plain_left_hand_p"/>
    <child link="hollie_plain_left_hand_t"/>
    <limit effort="1000.0" lower="0" upper="1.394" velocity="1"/>
    <origin rpy="0 0 0" xyz="0.026 0 0"/>
    <axis xyz="0 0 1"/>
    <mimic joint="hollie_plain_left_hand_Index_Finger_Distal" multiplier="1.0450" offset="0"/>
  </joint>
  <joint name="hollie_plain_left_hand_Middle_Finger_Proximal" type="revolute">
    <parent link="hollie_plain_left_hand_virtual_k"/>
    <child link="hollie_plain_left_hand_k"/>
    <limit effort="1000.0" lower="0.0" upper="0.79849" velocity="1"/>
    <origin rpy="-1.5707 0 0" xyz="0 0 0"/>
    <axis xyz="0 0 1"/>
  </joint>
  <joint name="hollie_plain_left_hand_Middle_Finger_Distal" type="revolute">
    <parent link="hollie_plain_left_hand_k"/>
    <child link="hollie_plain_left_hand_o"/>
    <limit effort="1000.0" lower="0" upper="1.334" velocity="1"/>
    <origin rpy="0 0 0" xyz="0.05004 0 0"/>
    <axis xyz="0 0 1"/>
  </joint>
  <joint name="hollie_plain_left_hand_j15" type="revolute">
    <parent link="hollie_plain_left_hand_o"/>
    <child link="hollie_plain_left_hand_s"/>
    <limit effort="1000.0" lower="0" upper="1.334" velocity="1"/>
    <origin rpy="0 0 0" xyz="0.032 0 0"/>
    <axis xyz="0 0 1"/>
    <mimic joint="hollie_plain_left_hand_Middle_Finger_Distal" multiplier="1.0454" offset="0"/>
  </joint>
  <joint name="hollie_plain_left_hand_Ring_Finger" type="revolute">
    <parent link="hollie_plain_left_hand_virtual_j"/>
    <child link="hollie_plain_left_hand_j"/>
    <limit effort="1000.0" lower="0.0" upper="0.98175" velocity="1"/>
    <origin rpy="1.5707 0 0" xyz="0 0 0"/>
    <axis xyz="0 0 1"/>
  </joint>
  <joint name="hollie_plain_left_hand_j12" type="revolute">
    <parent link="hollie_plain_left_hand_j"/>
    <child link="hollie_plain_left_hand_n"/>
    <limit effort="1000.0" lower="0" upper="1.334" velocity="1"/>
    <origin rpy="0 0 0" xyz="0.05004 0 0"/>
    <axis xyz="0 0 1"/>
    <mimic joint="hollie_plain_left_hand_Ring_Finger" multiplier="1.3588" offset="0"/>
  </joint>
  <joint name="hollie_plain_left_hand_j16" type="revolute">
    <parent link="hollie_plain_left_hand_n"/>
    <child link="hollie_plain_left_hand_r"/>
    <limit effort="1000.0" lower="0" upper="1.395" velocity="1"/>
    <origin rpy="0 0 0" xyz="0.032 0 0"/>
    <axis xyz="0 0 1"/>
    <mimic joint="hollie_plain_left_hand_Ring_Finger" multiplier="1.42093" offset="0"/>
  </joint>
  <joint name="hollie_plain_left_hand_Pinky" type="revolute">
    <parent link="hollie_plain_left_hand_virtual_i"/>
    <child link="hollie_plain_left_hand_i"/>
    <limit effort="1000.0" lower="0.0" upper="0.98175" velocity="1"/>
    <origin rpy="1.5707 0 0" xyz="0 0 0"/>
    <axis xyz="0 0 1"/>
  </joint>
  <joint name="hollie_plain_left_hand_j13" type="revolute">
    <parent link="hollie_plain_left_hand_i"/>
    <child link="hollie_plain_left_hand_m"/>
    <limit effort="1000.0" lower="0" upper="1.334" velocity="1"/>
    <origin rpy="0 0 0" xyz="0.04454 0 0"/>
    <axis xyz="0 0 1"/>
    <mimic joint="hollie_plain_left_hand_Pinky" multiplier="1.35880" offset="0"/>
  </joint>
  <joint name="hollie_plain_left_hand_j17" type="revolute">
    <parent link="hollie_plain_left_hand_m"/>
    <child link="hollie_plain_left_hand_q"/>
    <limit effort="1000.0" lower="0" upper="1.3971" velocity="1"/>
    <origin rpy="0 0 0" xyz="0.022 0 0"/>
    <axis xyz="0 0 1"/>
    <mimic joint="hollie_plain_left_hand_Pinky" multiplier="1.42307" offset="0"/>
  </joint>
  <joint name="hollie_plain_left_hand_index_spread" type="revolute">
    <parent link="hollie_plain_left_hand_d2"/>
    <child link="hollie_plain_left_hand_virtual_l"/>
    <limit effort="1000.0" lower="0.0" upper="0.28833" velocity="1"/>
    <origin rpy="0 -1.5707 1.5707" xyz="0.025 0 0.110"/>
    <axis xyz="0 0 -1.0"/>
    <mimic joint="hollie_plain_left_hand_Finger_Spread" multiplier="0.5" offset="0"/>
  </joint>
  <joint name="hollie_plain_left_hand_middle_spread_dummy" type="fixed">
    <parent link="hollie_plain_left_hand_d"/>
    <child link="hollie_plain_left_hand_virtual_k"/>
    <origin rpy="0 -1.5707 1.5707" xyz="0 0 0.110"/>
  </joint>
  <joint name="hollie_plain_left_hand_ring_spread" type="revolute">
    <parent link="hollie_plain_left_hand_e5"/>
    <child link="hollie_plain_left_hand_virtual_j"/>
    <limit effort="1000.0" lower="0.0" upper="0.28833" velocity="1"/>
    <origin rpy="-1.5707 -1.5707 0" xyz="-0.003855 0 0.0655"/>
    <axis xyz="0 0 -1.0"/>
    <mimic joint="hollie_plain_left_hand_Finger_Spread" multiplier="0.5" offset="0"/>
  </joint>
  <joint name="hollie_plain_left_hand_Finger_Spread" type="revolute">
    <parent link="hollie_plain_left_hand_e4"/>
    <child link="hollie_plain_left_hand_virtual_i"/>
    <limit effort="1000.0" lower="0.0" upper="0.5829" velocity="1"/>
    <origin rpy="-1.5707 -1.5707 0" xyz="-0.025355 0 0.056"/>
    <axis xyz="0 0 -1.0"/>
  </joint>
</robot>

