<?xml version="1.0" ?>
<!-- =================================================================================== -->
<!-- |    This document was autogenerated by xacro from shared_workspace.urdf.xacro    | -->
<!-- |    EDITING THIS FILE BY HAND IS NOT RECOMMENDED                                 | -->
<!-- =================================================================================== -->
<robot name="shared_workspace" xmlns:controller="http://playerstage.sourceforge.net/gazebo/xmlschema/#controller" xmlns:interface="http://playerstage.sourceforge.net/gazebo/xmlschema/#interface" xmlns:sensor="http://playerstage.sourceforge.net/gazebo/xmlschema/#sensor" xmlns:xacro="http://www.ros.org/wiki/xacro">
  <!-- Required arguments: 
       name_prefix : a prefix for all the frames as workaround for the tf_prefix
  -->
  <link name="world"/>
  <joint name="table_offset_joint" type="fixed">
    <parent link="world"/>
    <child link="table"/>
    <origin rpy="0 0 0" xyz="1.9 2.6 0"/>
  </joint>
  <link name="table">
    <visual>
      <material name="alu">
        <color rgba="0.5 0.5 0.5 1"/>
      </material>
      <geometry>
        <mesh filename="package://shared_workspace_description/meshes/worktable.stl"/>
      </geometry>
      <origin rpy="0 0 0" xyz="0 0 0"/>
    </visual>
    <collision>
      <geometry>
        <mesh filename="package://shared_workspace_description/meshes/worktable.stl"/>
      </geometry>
      <origin rpy="0 0 0" xyz="0 0 0"/>
    </collision>
    <!-- collision dummys -->
    <!-- collision_back_wall -->
    <collision>
      <origin rpy="0 0 0" xyz="0 -1.25 1.525"/>
      <geometry>
        <box size="0.04 2.5 1.05"/>
      </geometry>
    </collision>
    <!-- collision_control_hpro -->
    <visual>
      <origin rpy="0 0 0" xyz="-0.10 -1.35 1.05"/>
      <geometry>
        <box size="0.20 0.25 0.15"/>
      </geometry>
    </visual>
    <collision>
      <origin rpy="0 0 0" xyz="-0.10 -1.35 1.05"/>
      <geometry>
        <box size="0.20 0.25 0.15"/>
      </geometry>
    </collision>
    <!-- collision_ceiling -->
    <collision>
      <origin rpy="0 0 0" xyz="-0.6 -1.25 2.07"/>
      <geometry>
        <box size="1.2 2.5 0.04"/>
      </geometry>
    </collision>
    <!-- collision_front_wall -->
    <collision>
      <origin rpy="0 0 0" xyz="-1.00 -1.82 1.525"/>
      <geometry>
        <box size="0.04 1.28 1.05"/>
      </geometry>
    </collision>
    <!-- collision_diagonal_wall -->
    <collision>
      <origin rpy="0 0 0.785398163397" xyz="-1.41 -0.79 1.525"/>
      <geometry>
        <box size="0.04 1.16 1.05"/>
      </geometry>
    </collision>
    <!-- collision_tv -->
    <visual>
      <origin rpy="0 0 0.25" xyz="-0.13 -0.47 1.4"/>
      <geometry>
        <box size="0.04 0.9 0.6"/>
      </geometry>
    </visual>
    <collision>
      <origin rpy="0 0 0.25" xyz="-0.13 -0.47 1.4"/>
      <geometry>
        <box size="0.04 0.9 0.6"/>
      </geometry>
    </collision>
    <!-- collision_left_wall -->
    <collision>
      <origin rpy="0 0 0" xyz="-0.90 0 1.525"/>
      <geometry>
        <box size="1.8 0.04 1.05"/>
      </geometry>
    </collision>
    <!-- collision_right_wall -->
    <collision>
      <origin rpy="0 0 0" xyz="-0.50 -2.45 1.525"/>
      <geometry>
        <box size="1.0 0.04 1.05"/>
      </geometry>
    </collision>
    <!-- TODO: collision small_tv, kinects, side walls. ?plates? -->
  </link>
  <!-- Use this, to quickly find a suitable robot position
  <link name="base_x" />
  <link name="base_y" />
  <link name="base_z" />

  <joint name="base_x_joint" type="prismatic">
    <parent link="table"/>
    <child link="base_x"/>
    <origin xyz="0 0 0"/>
    <axis xyz="1 0 0"/>
    <limit effort="1000.0" lower="-2.0" upper="2.0" velocity="0.5"/>
  </joint>

  <joint name="base_y_joint" type="prismatic">
    <parent link="base_x"/>
    <child link="base_y"/>
    <origin xyz="0 0 0"/>
    <axis xyz="0 1 0"/>
    <limit effort="1000.0" lower="-2.0" upper="2.0" velocity="0.5"/>
  </joint>

  <joint name="base_z_joint" type="prismatic">
    <parent link="base_y"/>
    <child link="base_z"/>
    <origin xyz="0 0 0"/>
    <axis xyz="0 0 1"/>
    <limit effort="1000.0" lower="-0.5" upper="0.5" velocity="0.5"/>
  </joint>

  <joint name="arm_offset_joint" type="fixed">
    <parent link="base_z"/>
    <child link="base_link"/>
    <origin xyz="-0.8 -1.23 2.05" rpy="3.1415 0 0"/>
    </joint> -->
  <!-- alternative fixed offset link for robot base -->
  <joint name="arm_offset_joint" type="fixed">
    <parent link="table"/>
    <child link="base_link"/>
    <origin rpy="3.1415 0 0" xyz="-0.68 -1.0 2.096"/>
  </joint>
  <gazebo>
    <plugin filename="libgazebo_ros_control.so" name="ros_control">
      <!--robotNamespace>/</robotNamespace-->
      <!--robotSimType>gazebo_ros_control/DefaultRobotHWSim</robotSimType-->
    </plugin>
    <!--
    <plugin name="gazebo_ros_power_monitor_controller" filename="libgazebo_ros_power_monitor.so">
      <alwaysOn>true</alwaysOn>
      <updateRate>1.0</updateRate>
      <timeout>5</timeout>
      <powerStateTopic>power_state</powerStateTopic>
      <powerStateRate>10.0</powerStateRate>
      <fullChargeCapacity>87.78</fullChargeCapacity>     
      <dischargeRate>-474</dischargeRate>
      <chargeRate>525</chargeRate>
      <dischargeVoltage>15.52</dischargeVoltage>
      <chargeVoltage>16.41</chargeVoltage>
    </plugin>
-->
  </gazebo>
  <!--
  Author: Kelsey Hawkins 
  Contributers: Jimmy Da Silva, Ajit Krisshna N L, Muhammad Asif Rana 
-->
  <!-- measured from model -->
  <!-- ========================= KINECT STUFF ====================== -->
  <!--88x52x65 offsetx:17/2-->
  <!-- angle offset between kinects in a pair should be 0.785 radian -->
  <!--
  <link name="kinect_1_link"/>
  <link name="kinect_2_link"/>
  <link name="kinect_3_link"/>
  <link name="kinect_4_link"/>
  
  <joint name="kinect_1_joint" type="floating">
    <parent link="table"/>
    <child link="kinect_1_link"/>
    <origin xyz="0.525 0 0.98" rpy="0 0.775 0"/>
  </joint>
  <joint name="kinect_2_joint" type="floating">
    <parent link="table"/>
    <child link="kinect_2_link"/>
    <origin xyz="0.525 0 0.98" rpy="0 -0.01 0"/>
  </joint>
  <joint name="kinect_3_joint" type="floating">
    <parent link="table"/>
    <child link="kinect_3_link"/>
    <origin xyz="-0.355 0 0.65" rpy="0 0.285 3.1415"/>
  </joint>
  <joint name="kinect_4_joint" type="floating">
    <parent link="table"/>
    <child link="kinect_4_link"/>
    <origin xyz="-0.355 0 0.65" rpy="0 -0.5 3.1415"/>
  </joint>
  -->
  <link name="base_link">
    <visual>
      <geometry>
        <mesh filename="package://ur_description/meshes/ur10/visual/base.dae"/>
      </geometry>
      <material name="LightGrey">
        <color rgba="0.7 0.7 0.7 1.0"/>
      </material>
    </visual>
    <collision>
      <geometry>
        <mesh filename="package://ur_description/meshes/ur10/collision/base.stl"/>
      </geometry>
    </collision>
    <inertial>
      <mass value="4.0"/>
      <origin rpy="0 0 0" xyz="0.0 0.0 0.0"/>
      <inertia ixx="0.0061063308908" ixy="0.0" ixz="0.0" iyy="0.0061063308908" iyz="0.0" izz="0.01125"/>
    </inertial>
  </link>
  <joint name="shoulder_pan_joint" type="revolute">
    <parent link="base_link"/>
    <child link="shoulder_link"/>
    <origin rpy="0.0 0.0 0.0" xyz="0.0 0.0 0.1273"/>
    <axis xyz="0 0 1"/>
    <limit effort="330.0" lower="-3.14159265" upper="3.14159265" velocity="2.16"/>
    <dynamics damping="0.0" friction="0.0"/>
  </joint>
  <link name="shoulder_link">
    <visual>
      <geometry>
        <mesh filename="package://ur_description/meshes/ur10/visual/shoulder.dae"/>
      </geometry>
      <material name="LightGrey">
        <color rgba="0.7 0.7 0.7 1.0"/>
      </material>
    </visual>
    <collision>
      <geometry>
        <mesh filename="package://ur_description/meshes/ur10/collision/shoulder.stl"/>
      </geometry>
    </collision>
    <inertial>
      <mass value="7.778"/>
      <origin rpy="0 0 0" xyz="0.0 0.0 0.0"/>
      <inertia ixx="0.0314743125769" ixy="0.0" ixz="0.0" iyy="0.0314743125769" iyz="0.0" izz="0.021875625"/>
    </inertial>
  </link>
  <joint name="shoulder_lift_joint" type="revolute">
    <parent link="shoulder_link"/>
    <child link="upper_arm_link"/>
    <origin rpy="0.0 1.570796325 0.0" xyz="0.0 0.220941 0.0"/>
    <axis xyz="0 1 0"/>
    <limit effort="330.0" lower="-3.14159265" upper="3.14159265" velocity="2.16"/>
    <dynamics damping="0.0" friction="0.0"/>
  </joint>
  <link name="upper_arm_link">
    <visual>
      <geometry>
        <mesh filename="package://ur_description/meshes/ur10/visual/upperarm.dae"/>
      </geometry>
      <material name="LightGrey">
        <color rgba="0.7 0.7 0.7 1.0"/>
      </material>
    </visual>
    <collision>
      <geometry>
        <mesh filename="package://ur_description/meshes/ur10/collision/upperarm.stl"/>
      </geometry>
    </collision>
    <inertial>
      <mass value="12.93"/>
      <origin rpy="0 0 0" xyz="0.0 0.0 0.306"/>
      <inertia ixx="0.421753803798" ixy="0.0" ixz="0.0" iyy="0.421753803798" iyz="0.0" izz="0.036365625"/>
    </inertial>
  </link>
  <joint name="elbow_joint" type="revolute">
    <parent link="upper_arm_link"/>
    <child link="forearm_link"/>
    <origin rpy="0.0 0.0 0.0" xyz="0.0 -0.1719 0.612"/>
    <axis xyz="0 1 0"/>
    <limit effort="150.0" lower="-3.14159265" upper="3.14159265" velocity="3.15"/>
    <dynamics damping="0.0" friction="0.0"/>
  </joint>
  <link name="forearm_link">
    <visual>
      <geometry>
        <mesh filename="package://ur_description/meshes/ur10/visual/forearm.dae"/>
      </geometry>
      <material name="LightGrey">
        <color rgba="0.7 0.7 0.7 1.0"/>
      </material>
    </visual>
    <collision>
      <geometry>
        <mesh filename="package://ur_description/meshes/ur10/collision/forearm.stl"/>
      </geometry>
    </collision>
    <inertial>
      <mass value="3.87"/>
      <origin rpy="0 0 0" xyz="0.0 0.0 0.28615"/>
      <inertia ixx="0.111069694097" ixy="0.0" ixz="0.0" iyy="0.111069694097" iyz="0.0" izz="0.010884375"/>
    </inertial>
  </link>
  <joint name="wrist_1_joint" type="revolute">
    <parent link="forearm_link"/>
    <child link="wrist_1_link"/>
    <origin rpy="0.0 1.570796325 0.0" xyz="0.0 0.0 0.5723"/>
    <axis xyz="0 1 0"/>
    <limit effort="54.0" lower="-3.14159265" upper="3.14159265" velocity="3.2"/>
    <dynamics damping="0.0" friction="0.0"/>
  </joint>
  <link name="wrist_1_link">
    <visual>
      <geometry>
        <mesh filename="package://ur_description/meshes/ur10/visual/wrist1.dae"/>
      </geometry>
      <material name="LightGrey">
        <color rgba="0.7 0.7 0.7 1.0"/>
      </material>
    </visual>
    <collision>
      <geometry>
        <mesh filename="package://ur_description/meshes/ur10/collision/wrist1.stl"/>
      </geometry>
    </collision>
    <inertial>
      <mass value="1.96"/>
      <origin rpy="0 0 0" xyz="0.0 0.0 0.0"/>
      <inertia ixx="0.0051082479567" ixy="0.0" ixz="0.0" iyy="0.0051082479567" iyz="0.0" izz="0.0055125"/>
    </inertial>
  </link>
  <joint name="wrist_2_joint" type="revolute">
    <parent link="wrist_1_link"/>
    <child link="wrist_2_link"/>
    <origin rpy="0.0 0.0 0.0" xyz="0.0 0.1149 0.0"/>
    <axis xyz="0 0 1"/>
    <limit effort="54.0" lower="-3.14159265" upper="3.14159265" velocity="3.2"/>
    <dynamics damping="0.0" friction="0.0"/>
  </joint>
  <link name="wrist_2_link">
    <visual>
      <geometry>
        <mesh filename="package://ur_description/meshes/ur10/visual/wrist2.dae"/>
      </geometry>
      <material name="LightGrey">
        <color rgba="0.7 0.7 0.7 1.0"/>
      </material>
    </visual>
    <collision>
      <geometry>
        <mesh filename="package://ur_description/meshes/ur10/collision/wrist2.stl"/>
      </geometry>
    </collision>
    <inertial>
      <mass value="1.96"/>
      <origin rpy="0 0 0" xyz="0.0 0.0 0.0"/>
      <inertia ixx="0.0051082479567" ixy="0.0" ixz="0.0" iyy="0.0051082479567" iyz="0.0" izz="0.0055125"/>
    </inertial>
  </link>
  <joint name="wrist_3_joint" type="revolute">
    <parent link="wrist_2_link"/>
    <child link="wrist_3_link"/>
    <origin rpy="0.0 0.0 0.0" xyz="0.0 0.0 0.1157"/>
    <axis xyz="0 1 0"/>
    <limit effort="54.0" lower="-3.14159265" upper="3.14159265" velocity="3.2"/>
    <dynamics damping="0.0" friction="0.0"/>
  </joint>
  <link name="wrist_3_link">
    <visual>
      <geometry>
        <mesh filename="package://ur_description/meshes/ur10/visual/wrist3.dae"/>
      </geometry>
      <material name="LightGrey">
        <color rgba="0.7 0.7 0.7 1.0"/>
      </material>
    </visual>
    <collision>
      <geometry>
        <mesh filename="package://ur_description/meshes/ur10/collision/wrist3.stl"/>
      </geometry>
    </collision>
    <inertial>
      <mass value="0.202"/>
      <origin rpy="0 0 0" xyz="0.0 0.0 0.0"/>
      <inertia ixx="0.000526462289415" ixy="0.0" ixz="0.0" iyy="0.000526462289415" iyz="0.0" izz="0.000568125"/>
    </inertial>
  </link>
  <joint name="ee_fixed_joint" type="fixed">
    <parent link="wrist_3_link"/>
    <child link="ee_link"/>
    <origin rpy="0.0 0.0 1.570796325" xyz="0.0 0.0922 0.0"/>
  </joint>
  <link name="ee_link">
    <collision>
      <geometry>
        <box size="0.01 0.01 0.01"/>
      </geometry>
      <origin rpy="0 0 0" xyz="-0.01 0 0"/>
    </collision>
  </link>
  <transmission name="shoulder_pan_trans">
    <type>transmission_interface/SimpleTransmission</type>
    <joint name="shoulder_pan_joint">
      <hardwareInterface>PositionJointInterface</hardwareInterface>
    </joint>
    <actuator name="shoulder_pan_motor">
      <mechanicalReduction>1</mechanicalReduction>
    </actuator>
  </transmission>
  <transmission name="shoulder_lift_trans">
    <type>transmission_interface/SimpleTransmission</type>
    <joint name="shoulder_lift_joint">
      <hardwareInterface>PositionJointInterface</hardwareInterface>
    </joint>
    <actuator name="shoulder_lift_motor">
      <mechanicalReduction>1</mechanicalReduction>
    </actuator>
  </transmission>
  <transmission name="elbow_trans">
    <type>transmission_interface/SimpleTransmission</type>
    <joint name="elbow_joint">
      <hardwareInterface>PositionJointInterface</hardwareInterface>
    </joint>
    <actuator name="elbow_motor">
      <mechanicalReduction>1</mechanicalReduction>
    </actuator>
  </transmission>
  <transmission name="wrist_1_trans">
    <type>transmission_interface/SimpleTransmission</type>
    <joint name="wrist_1_joint">
      <hardwareInterface>PositionJointInterface</hardwareInterface>
    </joint>
    <actuator name="wrist_1_motor">
      <mechanicalReduction>1</mechanicalReduction>
    </actuator>
  </transmission>
  <transmission name="wrist_2_trans">
    <type>transmission_interface/SimpleTransmission</type>
    <joint name="wrist_2_joint">
      <hardwareInterface>PositionJointInterface</hardwareInterface>
    </joint>
    <actuator name="wrist_2_motor">
      <mechanicalReduction>1</mechanicalReduction>
    </actuator>
  </transmission>
  <transmission name="wrist_3_trans">
    <type>transmission_interface/SimpleTransmission</type>
    <joint name="wrist_3_joint">
      <hardwareInterface>PositionJointInterface</hardwareInterface>
    </joint>
    <actuator name="wrist_3_motor">
      <mechanicalReduction>1</mechanicalReduction>
    </actuator>
  </transmission>
  <!-- nothing to do here at the moment -->
  <!-- ROS base_link to UR 'Base' Coordinates transform -->
  <link name="base"/>
  <joint name="base_link-base_fixed_joint" type="fixed">
    <!-- NOTE: this rotation is only needed as long as base_link itself is
                 not corrected wrt the real robot (ie: rotated over 180
                 degrees)
      -->
    <origin rpy="0 0 -3.14159265" xyz="0 0 0"/>
    <parent link="base_link"/>
    <child link="base"/>
  </joint>
  <!-- Frame coincident with all-zeros TCP on UR controller -->
  <link name="tool0"/>
  <joint name="wrist_3_link-tool0_fixed_joint" type="fixed">
    <origin rpy="-1.570796325 0 0" xyz="0 0.0922 0"/>
    <parent link="wrist_3_link"/>
    <child link="tool0"/>
  </joint>
  <!-- mounting plate -->
  <link name="sensor_mounting_plate">
    <visual>
      <origin rpy="0 3.14159265 0" xyz="0 0 -0.01"/>
      <geometry>
        <mesh filename="package://shared_workspace_description/meshes/sensor_mounting_plate.dae" scale="0.001 0.001 0.001"/>
      </geometry>
    </visual>
  </link>
  <joint name="sensor_mounting_plate_joint" type="fixed">
    <origin rpy="0 0 0" xyz="0 0 0.01"/>
    <parent link="tool0"/>
    <child link="sensor_mounting_plate"/>
  </joint>
  <!-- mount the fts to the robot -->
  <joint name="fts_fix" type="fixed">
    <!--In most cases origin would be flange adapter plate: <origin xyz="0 0 0.009" rpy="0 0 0"/> /-->
    <origin rpy="0.0 0.0 -1.570796325" xyz="0 0 -0.002"/>
    <parent link="sensor_mounting_plate"/>
    <child link="fts_robotside"/>
  </joint>
  <link name="fts_robotside">
    <inertial>
      <origin rpy="0 0 0" xyz="0 0 0.01875"/>
      <mass value="0.65"/>
      <inertia ixx="0.000661171875" ixy="0" ixz="0" iyy="0.000661171875" iyz="0" izz="0.00117"/>
    </inertial>
    <visual>
      <origin rpy="0 0 0" xyz="0 0 0"/>
      <geometry>
        <mesh filename="package://robotiq_force_torque_sensor/meshes/visual/robotiq_fts150.stl"/>
      </geometry>
      <material name="black"/>
    </visual>
    <collision>
      <origin rpy="0 0 0" xyz="0 0 0"/>
      <geometry>
        <mesh filename="package://robotiq_force_torque_sensor/meshes/collision/robotiq_fts150.stl"/>
      </geometry>
    </collision>
  </link>
  <!-- virtual measurement frame -->
  <joint name="measurment_joint" type="fixed">
    <origin rpy="0 0 0" xyz="0 0 0.01625"/>
    <parent link="fts_robotside"/>
    <child link="robotiq_force_torque_frame_id"/>
  </joint>
  <link name="robotiq_force_torque_frame_id"/>
  <!-- toolside frame -->
  <joint name="toolside_joint" type="fixed">
    <origin rpy="0 0 0" xyz="0 0 0.0375"/>
    <parent link="fts_robotside"/>
    <child link="fts_toolside"/>
  </joint>
  <link name="fts_toolside"/>
  <!-- mount the tool to the robot -->
  <joint name="screwdriver_joint" type="fixed">
    <parent link="fts_toolside"/>
    <child link="screwdriver_flange"/>
    <origin rpy="0 0 0.628396325" xyz="0 0 0"/>
  </joint>
  <link name="screwdriver_flange">
    <inertial>
      <origin rpy="0 0 0" xyz="0 0 0"/>
      <mass value="0.1"/>
      <inertia ixx="0.01" ixy="0" ixz="0" iyy="0.01" iyz="0" izz="0.01"/>
    </inertial>
    <visual>
      <origin rpy="0 0 0" xyz="0 0 0"/>
      <geometry>
        <mesh filename="package://shared_workspace_description/meshes/screwing_tool_coarse_vis.stl"/>
      </geometry>
      <material name="greyish">
        <color rgba="0.8 0.8 0.8 1"/>
      </material>
    </visual>
    <collision>
      <origin rpy="0 0 0" xyz="0 0 0"/>
      <geometry>
        <mesh filename="package://shared_workspace_description/meshes/screwing_tool_col.stl"/>
      </geometry>
    </collision>
  </link>
  <joint name="tool_screwdriver_center_joint" type="fixed">
    <origin rpy="-0.7853981625 0 0" xyz="0 0 0.10"/>
    <parent link="screwdriver_flange"/>
    <child link="tool_screwdriver_center_link"/>
  </joint>
  <link name="tool_screwdriver_center_link">
    <inertial>
      <origin rpy="0 0 0" xyz="0 0 0"/>
      <mass value="1.0"/>
      <inertia ixx="0.01" ixy="0" ixz="0" iyy="0.01" iyz="0" izz="0.01"/>
    </inertial>
  </link>
  <joint name="tool_screwdriver_bit_joint" type="fixed">
    <origin rpy="0 0 0" xyz="0 0 0.11"/>
    <parent link="tool_screwdriver_center_link"/>
    <child link="tool_screwdriver_bit_link"/>
  </joint>
  <link name="tool_screwdriver_bit_link"/>
  <joint name="tool_screwdriver_tip_joint" type="fixed">
    <origin rpy="0 0 0" xyz="0 0 0.035"/>
    <parent link="tool_screwdriver_bit_link"/>
    <child link="tool_screwdriver_tip_link"/>
  </joint>
  <link name="tool_screwdriver_tip_link"/>
  <!-- mount the plate to the tabel -->
  <joint name="plate_0_joint" type="fixed">
    <origin rpy="0 0 0" xyz="-0.5 -0.5 1.0"/>
    <parent link="table"/>
    <child link="plate_0"/>
  </joint>
  <link name="plate_0">
    <visual>
      <origin rpy="0 0 0" xyz="0.075 0.15 0"/>
      <geometry>
        <box size="0.15 0.3 0.01"/>
      </geometry>
      <material name="greyish">
        <color rgba="0.8 0.8 0.8 1"/>
      </material>
    </visual>
  </link>
  <joint name="plate_0_screw_0_joint" type="fixed">
    <origin rpy="0 0 0" xyz="0.01 0.0812 0.02"/>
    <parent link="plate_0"/>
    <child link="plate_0_screw_0"/>
  </joint>
  <joint name="plate_0_screw_1_joint" type="fixed">
    <origin rpy="0 0 0" xyz="0.04 0.0812 0.02"/>
    <parent link="plate_0"/>
    <child link="plate_0_screw_1"/>
  </joint>
  <joint name="plate_0_screw_2_joint" type="fixed">
    <origin rpy="0 0 0" xyz="0.0345 0.109 0.02"/>
    <parent link="plate_0"/>
    <child link="plate_0_screw_2"/>
  </joint>
  <joint name="plate_0_screw_3_joint" type="fixed">
    <origin rpy="0 0 0" xyz="0.1153 0.109 0.02"/>
    <parent link="plate_0"/>
    <child link="plate_0_screw_3"/>
  </joint>
  <joint name="plate_0_screw_4_joint" type="fixed">
    <origin rpy="0 0 0" xyz="0.1153 0.191 0.02"/>
    <parent link="plate_0"/>
    <child link="plate_0_screw_4"/>
  </joint>
  <joint name="plate_0_screw_5_joint" type="fixed">
    <origin rpy="0 0 0" xyz="0.0345 0.191 0.02"/>
    <parent link="plate_0"/>
    <child link="plate_0_screw_5"/>
  </joint>
  <joint name="plate_0_screw_6_joint" type="fixed">
    <origin rpy="0 0 0" xyz="0.040 0.219 0.02"/>
    <parent link="plate_0"/>
    <child link="plate_0_screw_6"/>
  </joint>
  <joint name="plate_0_screw_7_joint" type="fixed">
    <origin rpy="0 0 0" xyz="0.010 0.219 0.02"/>
    <parent link="plate_0"/>
    <child link="plate_0_screw_7"/>
  </joint>
  <link name="plate_0_screw_0"/>
  <link name="plate_0_screw_1"/>
  <link name="plate_0_screw_2"/>
  <link name="plate_0_screw_3"/>
  <link name="plate_0_screw_4"/>
  <link name="plate_0_screw_5"/>
  <link name="plate_0_screw_6"/>
  <link name="plate_0_screw_7"/>
  <!-- mount the plate to the tabel -->
  <joint name="plate_1_joint" type="fixed">
    <origin rpy="0 0 0" xyz="-0.5 -1.5 1.0"/>
    <parent link="table"/>
    <child link="plate_1"/>
  </joint>
  <link name="plate_1">
    <visual>
      <origin rpy="0 0 0" xyz="0.3 0.3 0"/>
      <geometry>
        <box size="0.6 0.6 0.01"/>
      </geometry>
      <material name="greyish">
        <color rgba="0.8 0.8 0.8 1"/>
      </material>
    </visual>
  </link>
  <joint name="plate_1_screw_0_joint" type="fixed">
    <origin rpy="0 0 0" xyz="0.500 0.075 0.02"/>
    <parent link="plate_1"/>
    <child link="plate_1_screw_0"/>
  </joint>
  <joint name="plate_1_screw_1_joint" type="fixed">
    <origin rpy="0 0 0" xyz="0.450 0.175 0.02"/>
    <parent link="plate_1"/>
    <child link="plate_1_screw_1"/>
  </joint>
  <joint name="plate_1_screw_2_joint" type="fixed">
    <origin rpy="0 0 0" xyz="0.450 0.474 0.02"/>
    <parent link="plate_1"/>
    <child link="plate_1_screw_2"/>
  </joint>
  <joint name="plate_1_screw_3_joint" type="fixed">
    <origin rpy="0 0 0" xyz="0.550 0.525 0.02"/>
    <parent link="plate_1"/>
    <child link="plate_1_screw_3"/>
  </joint>
  <joint name="plate_1_screw_4_joint" type="fixed">
    <origin rpy="0 0 0" xyz="0.114 0.512 0.02"/>
    <parent link="plate_1"/>
    <child link="plate_1_screw_4"/>
  </joint>
  <joint name="plate_1_screw_5_joint" type="fixed">
    <origin rpy="0 0 0" xyz="0.185 0.389 0.02"/>
    <parent link="plate_1"/>
    <child link="plate_1_screw_5"/>
  </joint>
  <joint name="plate_1_screw_6_joint" type="fixed">
    <origin rpy="0 0 0" xyz="0.100 0.200 0.02"/>
    <parent link="plate_1"/>
    <child link="plate_1_screw_6"/>
  </joint>
  <joint name="plate_1_screw_7_joint" type="fixed">
    <origin rpy="0 0 0" xyz="0.200 0.100 0.02"/>
    <parent link="plate_1"/>
    <child link="plate_1_screw_7"/>
  </joint>
  <link name="plate_1_screw_0"/>
  <link name="plate_1_screw_1"/>
  <link name="plate_1_screw_2"/>
  <link name="plate_1_screw_3"/>
  <link name="plate_1_screw_4"/>
  <link name="plate_1_screw_5"/>
  <link name="plate_1_screw_6"/>
  <link name="plate_1_screw_7"/>
</robot>

